Workbook

Sheet Grobkonzept
U1: Nutzereingaben | AO1: Datenstufe 1 | AQ1: Datenstufe 2 | AU1: Datenstufe 3
U2: Gebäude Allgemein
AB3: Baujahr | AO3: keine | AQ3: Eingabe | AU3: Eingabe
AB4: Bewohner | AO4: keine | AQ4: Eingabe | AU4: Eingabe
AB5: Sanierungszustand | AI5: (schlecht mittel gut) | AO5: keine | AQ5: keine | AU5: Eingabe
U7: Dach
AB8: Alter des Bauteils | AO8: keine | AQ8: Eingabe | AU8: Eingabe
AB9: Fläche (Hüllflächenanteil) | AO9: keine | AQ9: Eingabe | AU9: Eingabe
AB10: Dachform | AO10: keine | AQ10: Eingabe | AU10: Eingabe
AB11: Dämmung vorhanden | AO11: keine | AQ11: Eingabe | AU11: Eingabe
AB12: Dämmschichtdicke | AO12: keine | AQ12: keine | AU12: Eingabe
AB13: Wärmeleitgruppe | AO13: keine | AQ13: keine | AU13: Eingabe
AB14: U-Wert Bestand | AI14: ggf. mit Link zu einem U-Wertrechenr | AO14: keine | AQ14: keine | AU14: Eingabe
U16: Oberste Geschossdecke (OGD)
AB17: Alter des Bauteils | AO17: keine | AQ17: Eingabe | AU17: Eingabe
AB18: Fläche (Hüllflächenanteil) | AO18: keine | AQ18: Eingabe | AU18: Eingabe
AB19: Dämmung vorhanden | AO19: keine | AQ19: Eingabe | AU19: Eingabe
AB20: Dämmschichtdicke | AO20: keine | AQ20: keine | AU20: Eingabe
AB21: Wärmeleitgruppe | AO21: keine | AQ21: keine | AU21: Eingabe
AB22: U-Wert Bestand | AO22: keine | AQ22: keine | AU22: Eingabe
U24: Außenwand
AB25: Alter des Bauteils | AO25: keine | AQ25: Eingabe | AU25: Eingabe
AB26: Fläche (Hüllflächenanteil) | AO26: keine | AQ26: Eingabe | AU26: Eingabe
AB27: Dämmung vorhanden | AO27: keine | AQ27: Eingabe | AU27: Eingabe
AB28: Dämmschichtdicke | AO28: keine | AQ28: keine | AU28: Eingabe
AB29: Wärmeleitgruppe | AO29: keine | AQ29: keine | AU29: Eingabe
AB30: U-Wert Bestand | AO30: keine | AQ30: keine | AU30: Eingabe
U32: Fenster/Türen
AB33: Alter des Bauteils | AO33: keine | AQ33: Eingabe | AU33: Eingabe
AB34: Fläche (Hüllflächenanteil) | AO34: keine | AQ34: Eingabe | AU34: Eingabe
AB35: U-Wert Bestand | AO35: keine | AQ35: keine | AU35: Eingabe
U37: Unterste Geschossdecek (UGD)
AB38: Alter des Bauteils | AO38: keine | AQ38: Eingabe | AU38: Eingabe
AB39: Fläche (Hüllflächenanteil) | AO39: keine | AQ39: Eingabe | AU39: Eingabe
AB40: Dämmung vorhanden | AO40: keine | AQ40: Eingabe | AU40: Eingabe
AB41: Dämmschichtdicke | AO41: keine | AQ41: keine | AU41: Eingabe
AB42: Wärmeleitgruppe | AO42: keine | AQ42: keine | AU42: Eingabe
AB43: U-Wert Bestand | AO43: keine | AQ43: keine | AU43: Eingabe
A46: Bestandsanalyse | B46: Weiterberechnung der für den Nutzer relevante Ergebnisse
AO47: Datenstufe 1 | AQ47: Datenstufe 2 | AU47: Datenstufe 2
...

Sheet Dach-Fenster
R2: Datenstufe 1 | T2: Datenstufe 2
C3: Dach | K3: Fläche A [m²] | R3: LOD oder Nutzereingabe der Fläche [m²] | T3: Nutzereingabe der Fläche | X3: Beispiel: | Z3: 0 | AA3: [m²]
L4: A = | M4: =Z3 -> 0 | T4: Dachfläche - Dachfensterfläche: | Z4: =Z3-Z15 -> 0 | AA4: [m²]
C5: HT [W/K] | K5: U-Wert [W/m²K] | R5: Baujahr über LOD oder Alterseingabe (gemäß Kat.1 U-Wert) | T5: Berechnung U-Wert über Nutzereingabe der Bauteilschichten | AE5: Dropdown-Menü entweder oder
D6: HT | E6: = | F6: U | G6: * | H6: A | K6: U | L6: = | M6: (1 | N6: / | O6: RT) | R6: Dachraum beheizt Ja / Nein | T6: Zwischensparren Dicke | X6: 0.2 | Y6: [m] | Z6: Festgelegt WLG | AB6: 0.04
D7: =F7*H7 -> 0 | E7: = | F7: =ROUND(K8,3) -> 0.254 | G7: * | H7: =M4 -> 0 | K7: =ROUND(M7/O7,3) -> 0.195 | L7: = | M7: 1 | N7: / | O7: =T10 -> 5.14 | R7: ='Kat. 1 U-Wert'!B9 -> Massive Konstruktion | S7: Flachdach | T7: Aufdachdämmung Dicke | X7: 0.2 | Y7: [m] | Z7: Festgelegt WLG | AB7: 0.04
K8: =M8*O8 -> 0.2535 | L8: = | M8: =K7 -> 0.195 | N8: * | O8: 1.3 | R8: ='Kat. 1 U-Wert'!B10 -> Holzkonstruktion | S8: Satteldach | T8: Stahlbetondecke 25cm mit R-Wert 0,11
T9: (RT,Zwischensparren | U9: = | V9: Rsi | W9: + | X9: ∑R (Dicke [m] | Y9: / | Z9: λ [W/mK]) | AA9: + | AB9: Rse) | AC9: * | AD9: Minderungsfaktor
T10: =V10+(X10/Z10)+AB10 -> 5.14 | U10: = | V10: ='Kat. 1 U-Wert'!C51 -> 0.1 | W10: + | X10: =X6 -> 0.2 | Y10: / | Z10: =AB6 -> 0.04 | AA10: + | AB10: ='Kat. 1 U-Wert'!C52 -> 0.04 | AC10: * | AD10: 0.3
K11: =ROUND(M11/O11,3) -> 0.191 | L11: = | M11: 1 | N11: / | O11: =T12 -> 5.2486957 | T11: RT,Aufsparren | U11: = | V11: Rsi | W11: + | X11: ∑R (Dicke [m] | Y11: / | Z11: λ [W/mK]) | AA11: + | AB11: Rse
K12: kein Korrekturfaktor | T12: =V12+(X12/Z12+X13/Z13)+AB12 -> 5.2486957 | U12: = | V12: ='Kat. 1 U-Wert'!C51 -> 0.1 | W12: + | X12: =X7 -> 0.2 | Y12: / | Z12: =AB7 -> 0.04 | AA12: + | AB12: ='Kat. 1 U-Wert'!C52 -> 0.04
X13: 0.25 | Y13: / | Z13: 2.3
C15: Dachfenster | K15: Fläche A [m²] | R15: LOD oder Nutzereingabe der Fläche [m²] | T15: Nutzereingabe der Fläche | X15: Beispiel: | Z15: =Z3*0.2 -> 0 | AA15: [m²]
D16: HT | E16: = | F16: F | G16: * | H16: U | I16: * | J16: A | K16: A | L16: = | M16: =Z15 -> 0
D17: =F17*H17*J17 -> 0 | E17: = | F17: 0.93 | G17: * | H17: =M18 -> 2 | I17: * | J17: =M16 -> 0 | K17: U-Wert [W/m²K] | R17: Baujahr über LOD oder Alterseingabe (U-Wert gemäß Kat. 1) | T17: Angabe des U-Werts über Nutzereingabe | Z17: Beispiel: | AA17: 2 | AB17: [W/m²K]
K18: U | L18: = | M18: =AA17 -> 2 | R18: ='Kat. 1 U-Wert'!B40 -> Holzfenster, zwei Scheiben | S18: (> 40 Jahre) | T18: oder Alterseingabe gemäß Kat.1 U-Wert über
R19: ='Kat. 1 U-Wert'!B42 -> Kunststofffenster, Isolierverglasung | S19: (< 40 Jahre) | T19: Rahmenart (Holz, Kunststoff; Aluminium/Stahl) und
T20: Glasart (Einfach; Zweifach; Dreifach)
B24: Dach saniert | H24: Dicke Dämmung NEU | K24: U-Wert NEU | M24: U-Wert VORH | P24: Lamda-Wert | R24: Sanierungsempfehlung über Baujahr nach Gebiet oder Nutzereingabe
B25: HT [W/K] | H25: [m] | K25: [W/m²K] | M25: [W/m²K] | P25: λ [W/mK]) | R25: (<20 Jahre Bewertung als neues Dach) | S25: keine Empfehlung | T25: Sanierungswunsch Ja / Nein Annahme Standardwärmedämmung Mineralwolle WLG (035) U-Wert gemäß BEG EM 0,14 [W/m²K]
B26: HT | C26: = | D26: U | E26: * | F26: A | H26: =ROUNDUP(H30,2) -> #DIV/0! | K26: ='Kat. 1 U-Wert'!F96 -> 0.14 | M26: =L14 -> 0 | P26: =AB7 -> 0.04
B27: =D27*F27 -> 0 | C27: = | D27: =K26 -> 0.14 | E27: * | F27: =M4 -> 0 | H27: einzubauende Dämmstärke | K27: gemäß BEG EM | M27: Bestand | P27: Dämmung Neu | R27: (20-40 Jahre Bewertung als sanierungsbedüftig) | S27: Empfehlung Dämmung | T27: aus Datenstufe 2 Bestandsaufnahme Annahme Standardwärmedämmung Mineralwolle WLG (035) U-Wert gemäß BEG EM 0,14 [W/m²K]
H29: dDä,NEU | J29: = | K29: (1/UNEU | M29: - | N29: 1/UVORH) | P29: * | Q29: λDä,NEU | R29: Dämmung >40 Jahre Bewertung als sanierungsbedürftig | S29: Komplettsanierung | T29: aus Datenstufe 2 Bestandsaufnahme Annahme Standardwärmedämmung Mineralwolle WLG (035) U-Wert gemäß BEG EM 0,14 [W/m²K]
H30: =(K30-N30)*Q30 -> #DIV/0! | J30: = | K30: =1/K26 -> 7.1428571 | M30: - | N30: =1/0 -> #DIV/0! | P30: * | Q30: =P26 -> 0.04
B32: Platzhalter für Kosten
B34: Dachfenster saniert | K34: U-Wert NEU | M34: U-Wert VORH | R34: Dachfenstertausch über Baujahr nach Gebiet oder Nutzereingabe
B35: HT [W/K] | K35: [W/m²K] | M35: [W/m²K] | R35: (<30 Jahre Bewertung als neueres Fenster) | S35: keine Empfehlung | T35: Sanierungswunsch Ja / Nein Standard-Kunststoffrahmen- oder Holzrahmenfenster U-Wert gemäß BEG EM 1,00 [W/m²K]
B36: HT | C36: = | D36: U | E36: * | F36: A | K36: ='Kat. 1 U-Wert'!F88 -> 1 | M36: =M18 -> 2
B37: =D37*F37 -> 0 | C37: = | D37: =K36 -> 1 | E37: * | F37: =M16 -> 0 | K37: gemäß BEG EM | M37: Bestand | R37: (>30 Jahre Bewertung als sanierungsbedürftig) | S37: Dachfenstertausch | T37: Abfrage: Standard-Kunststoffrahmen- oder Holzrahmenfenster U-Wert gemäß BEG EM 1,00 [W/m²K]
B39: Platzhalter für Kosten

Sheet OGD
R2: Datenstufe 1 | T2: Datenstufe 2
C3: OGD | K3: Fläche A [m²] | R3: LOD Grundfläche oder Nutzereingabe der Fläche [m²] | T3: Nutzereingabe der Fläche | X3: Beispiel: | Z3: 77 | AA3: [m²]
K4: A | L4: = | M4: =Z3 -> 77
C5: HT [W/K] | K5: U-Wert [W/m²K] | R5: Baujahr über LOD oder Alterseingabe (gemäß Kat.1 U-Wert) | T5: Berechnung U-Wert über Nutzereingabe der Bauteilschichten
D6: HT | E6: = | F6: U | G6: * | H6: A | K6: U | L6: = | M6: (1 | N6: / | O6: RT) | R6: Dachraum beheizt Ja/Nein | T6: ='Kat. 1 U-Wert'!B12 -> Massive Decke | Y6: (gemäß Kat.1 U-Wert) | AB6: ='Kat. 1 U-Wert'!F13 -> 0.7
D7: =F7*H7 -> 53.9 | E7: = | F7: =K7 -> 0.7 | G7: * | H7: =M4 -> 77 | K7: =M7/O7 -> 0.7 | L7: = | M7: 1 | N7: / | O7: =X14+Z14 -> 1.4285714 | R7: ='Kat. 1 U-Wert'!B12 -> Massive Decke | S7: (< 60 Jahre) | T7: ='Kat. 1 U-Wert'!B13 -> Holzbalkendecke | Y7: (gemäß Kat.1 U-Wert)
R8: ='Kat. 1 U-Wert'!B13 -> Holzbalkendecke | S8: (> 60 Jahre) | T8: Dämmschichtdicke | X8: 0 | Y8: [m] | Z8: Festgelegt WLG | AB8: 0.032
T9: RT,Dämmung | U9: = | V9: Rsi | W9: + | X9: ∑R (Dicke [m] | Y9: / | Z9: λ [W/mK]) | AA9: + | AB9: Rse
T10: =V10+(X10/Z10)+AB10 -> 0 | U10: = | V10: =IF(X8>0,'Kat. 1 U-Wert'!C51,0) -> 0 | W10: + | X10: =X8 -> 0 | Y10: / | Z10: =AB8 -> 0.032 | AA10: + | AB10: =IF(X8>0,'Kat. 1 U-Wert'!C52,0) -> 0
T11: RTDecke | U11: = | V11: 1 | W11: / | X11: (gemäß Kat.1 U-Wert)
T12: =V12/X12 -> 1.4285714 | U12: = | V12: 1 | W12: / | X12: =AB6 -> 0.7
T13: RT | U13: = | X13: (RTDecke | Y13: + | Z13: RT,Dämmung)
T14: =X14+Z14 -> 1.4285714 | U14: = | X14: =T12 -> 1.4285714 | Y14: + | Z14: =T10 -> 0
B17: OGD saniert | H17: Dicke Dämmung NEU | K17: U-Wert NEU | M17: U-Wert VORH | P17: Lamda-Wert | R17: Sanierungsempfehlung über Baujahr nach Gebiet oder Nutzereingabe
B18: HT [W/K] | H18: [m] | K18: [W/m²K] | M18: [W/m²K] | P18: λ [W/mK]) | R18: Oberste Geschossdecke gedämmt | S18: keine Empfehlung | U18: Sanierungswunsch Ja / Nein Annahme Standardwärmedämmung EPS/XPS WLG (032) U-Wert gemäß BEG EM 0,14 [W/m²K]
B19: HT | C19: = | D19: U | E19: * | F19: A | H19: =_xlfn.CEILING.MATH(H23,0.02) -> 0.2 | K19: ='Kat. 1 U-Wert'!F98 -> 0.14 | M19: =K7 -> 0.7 | P19: =AB8 -> 0.032
B20: =D20*F20 -> 10.78 | C20: = | D20: =K19 -> 0.14 | E20: * | F20: =M4 -> 77 | H20: einzubauende Dämmstärke | K20: gemäß BEG EM | M20: Bestand | P20: Dämmung Neu | R20: Oberste Geschossdecke nicht gedämmt | S20: Empfehlung Dämmung | U20: aus Datenstufe 2 Bestandsaufnahme Annahme Standardwärmedämmung EPS/XPS WLG (032) U-Wert gemäß BEG EM 0,14 [W/m²K]
H22: dDä,NEU | J22: = | K22: (1/UNEU | M22: - | N22: 1/UVORH) | P22: * | Q22: λDä,NEU | R22: Dämmung >40 Jahre Bewertung als sanierungsbedürftig | S22: Komplettsanierung | U22: aus Datenstufe 2 Bestandsaufnahme Annahme Standardwärmedämmung EPS/XPS WLG (032) U-Wert gemäß BEG EM 0,14 [W/m²K]
H23: =(K23-N23)*Q23 -> 0.18285714 | J23: = | K23: =1/K19 -> 7.1428571 | M23: - | N23: =1/K7 -> 1.4285714 | P23: * | Q23: =P19 -> 0.032
B25: Platzhalter für Kosten

Sheet AW-Fenster
S2: Datenstufe 1 | U2: Datenstufe 2
D3: AW | L3: Fläche A [m²] | S3: LOD (Umfang aus Grundfläche x Höhe - Fensterflächenanteil ca. 30%) (ausschließlich für unbeheizte Kellerräume) oder Nutzereingabe der Fläche [m²] | U3: Nutzereingabe der Fläche | Y3: Beispiel: | AA3: 212 | AB3: [m²]
L4: A | M4: = | N4: =AA4 -> 169.6 | U4: Außenwandfläche - Fensterfläche: | AA4: =AA3-AA16 -> 169.6 | AB4: [m²]
L5: U-Wert [W/m²K] | S5: Baujahr über LOD oder Alterseingabe (gemäß Kat.1 U-Wert) | U5: Berechnung U-Wert über Nutzereingabe der Bauteilschichten
D6: HT [W/K] | L6: =ROUND(N6/P6,3) -> 1.4 | M6: = | N6: 1 | O6: / | P6: =U14 -> 0.71428571 | S6: Massivwand mit WDVS (0,20 W/m²K) | T6: (< 20 Jahre) | U6: Außenwandkonstruktion (gemäß Kat.1 U-Wert) | AC6: ='Kat. 1 U-Wert'!F22 -> 1.4
E7: HT | F7: = | G7: F | H7: * | I7: U | J7: * | K7: A | S7: ='Kat. 1 U-Wert'!B22 -> Sonstige Wandaufbauten über 20cm Wandstärke | T7: (> 20 - 70 Jahre)
E8: =G8*I8*K8 -> 237.44 | F8: = | G8: 1 | H8: * | I8: =L6 -> 1.4 | J8: * | K8: =N4 -> 169.6 | S8: ='Kat. 1 U-Wert'!B19 -> Wie vorstehend, jedoch über 30cm Wandstärke | T8: (> 70 Jahre) | U8: Dämmschichtdicke | Y8: 0 | Z8: [m] | AA8: Festgelegt WLG | AC8: 0.035
U9: RT,Dämmung | V9: = | W9: Rsi | X9: + | Y9: ∑R (Dicke [m] | Z9: / | AA9: λ [W/mK]) | AB9: + | AC9: Rse
U10: =W10+(Y10/AA10)+AC10 -> 0 | V10: = | W10: =IF(Y8>0,'Kat. 1 U-Wert'!C51,0) -> 0 | X10: + | Y10: =Y8 -> 0 | Z10: / | AA10: =AC8 -> 0.035 | AB10: + | AC10: =IF(Y8>0,'Kat. 1 U-Wert'!C52,0) -> 0
U11: RTAußenwand | V11: = | W11: 1 | X11: / | Y11: (gemäß Kat.1 U-Wert)
U12: =W12/Y12 -> 0.71428571 | V12: = | W12: 1 | X12: / | Y12: =AC6 -> 1.4
U13: RT | V13: = | Y13: (RTAußenwand | Z13: + | AA13: RT,Dämmung)
U14: =Y14+AA14 -> 0.71428571 | V14: = | Y14: =U12 -> 0.71428571 | Z14: + | AA14: =U10 -> 0
D16: Fenster/ Türen | L16: Fläche A [m²] | S16: Flächenanteil LOD (35% der Gesamtaußenwandfläche) oder Nutzeingabe der Fläche | U16: Nutzereingabe der Fläche | Y16: Beispiel: | AA16: =AA3*0.2 -> 42.4 | AB16: [m²]
L17: A | M17: = | N17: =AA16 -> 42.4 | O17: m²
D18: HT [W/K] | L18: U-Wert [W/m²K] | S18: Baujahr über LOD oder Alterseingabe (gemäß Kat.1 U-Wert) | U18: Angabe des U-Werts über Nutzereingabe | AA18: Beispiel: | AB18: ='Kat. 1 U-Wert'!I40 -> 2.7 | AC18: [W/m²K]
E19: HT | F19: = | G19: F | H19: * | I19: U | J19: * | K19: A | L19: U | M19: = | N19: =AB18 -> 2.7 | S19: ='Kat. 1 U-Wert'!B40 -> Holzfenster, zwei Scheiben | T19: (> 40 Jahre) | U19: oder Alterseingabe gemäß Kat.1 U-Wert über
E20: =G20*I20*K20 -> 114.48 | F20: = | G20: 1 | H20: * | I20: =N19 -> 2.7 | J20: * | K20: =N17 -> 42.4 | S20: ='Kat. 1 U-Wert'!B42 -> Kunststofffenster, Isolierverglasung | T20: (< 40 Jahre) | U20: Rahmenart (Holz, Kunststoff; Aluminium/Stahl) und
U21: Glasart (Einfach; Zweifach; Dreifach)
C25: AW saniert | I25: Dicke Dämmung NEU | L25: U-Wert NEU | N25: U-Wert VORH | Q25: Lamda-Wert | S25: Sanierungsempfehlung über Baujahr nach Gebiet oder Nutzereingabe
C26: HT [W/K] | I26: [m] | L26: [W/m²K] | N26: [W/m²K] | Q26: λ [W/mK]) | S26: Außenwand gedämmt | T26: keine Empfehlung | V26: Sanierungswunsch Ja / Nein Annahme Standardwärmedämmung EPS WLG (035) U-Wert gemäß BEG EM 0,20 [W/m²K]
C27: HT | D27: = | E27: U | F27: * | G27: A | I27: =_xlfn.CEILING.MATH(I31,0.02) -> 0.16 | L27: ='Kat. 1 U-Wert'!F67 -> 0.2 | N27: =L6 -> 1.4 | Q27: =AC8 -> 0.035
C28: =E28*G28 -> 34 | D28: = | E28: =L27 -> 0.2 | F28: * | G28: =ROUNDUP(N4,0) -> 170 | I28: einzubauende Dämmstärke | L28: gemäß BEG EM | N28: Bestand | Q28: Dämmung Neu | S28: Außenwand nicht gedämmt | T28: Empfehlung Dämmung | V28: aus Datenstufe 2 Bestandsaufnahme Annahme Standardwärmedämmung EPS WLG (035) U-Wert gemäß BEG EM 0,20 [W/m²K]
I30: dDä,NEU | K30: = | L30: (1/UNEU | N30: - | O30: 1/UVORH) | Q30: * | R30: λDä,NEU | S30: Dämmung >50 Jahre Bewertung als sanierungsbedürftig | T30: Empfehlung Dämmungaustausch | V30: aus Datenstufe 2 Bestandsaufnahme Annahme Standardwärmedämmung EPS WLG (035) U-Wert gemäß BEG EM 0,20 [W/m²K]
I31: =(L31-O31)*R31 -> 0.15 | K31: = | L31: =1/L27 -> 5 | N31: - | O31: =1/N27 -> 0.71428571 | Q31: * | R31: =Q27 -> 0.035
C33: Platzhalter für Kosten
C35: Fenster/ Türen saniert | L35: U-Wert NEU | N35: U-Wert VORH | S35: Dachfenstertausch über geschätztes Baujahr nach Gebiet oder Nutzereingabe
C36: HT [W/K] | L36: [W/m²K] | N36: [W/m²K] | S36: (<30 Jahre Bewertung als neueres Fenster) | T36: keine Empfehlung | V36: Sanierungswunsch Ja / Nein Standard-Kunststoffrahmen- oder Holzrahmenfenster U-Wert gemäß BEG EM 0,95 [W/m²K]
C37: HT | D37: = | E37: U | F37: * | G37: A | L37: ='Kat. 1 U-Wert'!F76 -> 0.95 | N37: =N19 -> 2.7
C38: =E38*G38 -> 40.28 | D38: = | E38: =L37 -> 0.95 | F38: * | G38: =N17 -> 42.4 | L38: gemäß BEG EM | N38: Bestand | S38: (>30 Jahre Bewertung als sanierungsbedürftig) | T38: Dachfenstertausch | V38: Abfrage: Standard-Kunststoffrahmen- oder Holzrahmenfenster U-Wert gemäß BEG EM 0,95 [W/m²K]
C40: Platzhalter für Kosten

Sheet UGD
R2: Datenstufe 1 | T2: Datenstufe 2
C3: UGD | K3: Fläche A [m²] | R3: LOD Grundfläche oder Nutzereingabe der Fläche [m²] | T3: Nutzereingabe der Fläche | X3: Beispiel: | Z3: 77 | AA3: [m²]
K4: A | L4: = | M4: =Z3 -> 77
C5: HT [W/K] | K5: U-Wert [W/m²K] | R5: Baujahr über LOD oder Alterseingabe (gemäß Kat.1 U-Wert) | T5: Berechnung U-Wert über Nutzereingabe der Bauteilschichten
D6: HT | E6: = | F6: U | G6: * | H6: A | K6: U | L6: = | M6: (1 | N6: / | O6: RT) | R6: ='Kat. 1 U-Wert'!B27 -> Kellerdecke Stahlbeton massiv | S6: (> 60 Jahre) | T6: ='Kat. 1 U-Wert'!B27 -> Kellerdecke Stahlbeton massiv | Y6: (gemäß Kat.1 U-Wert) | AB6: ='Kat. 1 U-Wert'!F27 -> 1
D7: =F7*H7 -> 77 | E7: = | F7: =K7 -> 1 | G7: * | H7: =M4 -> 77 | K7: =M7/O7 -> 1 | L7: = | M7: 1 | N7: / | O7: =T10+T12 -> 1 | R7: ='Kat. 1 U-Wert'!B28 -> Kellerdecke als Holzbalkendecke | S7: (< 60 Jahre) | T7: ='Kat. 1 U-Wert'!B28 -> Kellerdecke als Holzbalkendecke | Y7: (gemäß Kat.1 U-Wert)
R8: ='Kat. 1 U-Wert'!B29 -> Boden gegen Erdreich, Stahlbeton massiv | S8: (beheizter Keller) | T8: Dämmschichtdicke | X8: 0 | Y8: [m] | Z8: Festgelegt WLG | AB8: 0.03
T9: RT,Dämmung | U9: = | V9: Rsi | W9: + | X9: ∑R (Dicke [m] | Y9: / | Z9: λ [W/mK]) | AA9: + | AB9: Rse
T10: =V10+(X10/Z10)+AB10 -> 0 | U10: = | V10: =IF(X8>0,'Kat. 1 U-Wert'!C51,0) -> 0 | W10: + | X10: =X8 -> 0 | Y10: / | Z10: =AB8 -> 0.03 | AA10: + | AB10: =IF(X8>0,'Kat. 1 U-Wert'!C52,0) -> 0
T11: RTDecke | U11: = | V11: 1 | W11: / | X11: (gemäß Kat.1 U-Wert)
T12: =V12/X12 -> 1 | U12: = | V12: 1 | W12: / | X12: =AB6 -> 1
T13: RT | U13: = | X13: (RTDecke | Y13: + | Z13: RT,Dämmung)
T14: =X14+Z14 -> 1 | U14: = | X14: =T12 -> 1 | Y14: + | Z14: =T10 -> 0
B17: UGD saniert | H17: Dicke Dämmung NEU | K17: U-Wert NEU | M17: U-Wert VORH | P17: Lamda-Wert | R17: Sanierungsempfehlung über Baujahr nach Gebiet oder Nutzereingabe
B18: HT [W/K] | H18: [m] | K18: [W/m²K] | M18: [W/m²K] | P18: λ [W/mK]) | R18: Unterste Geschossdecke gedämmt | S18: keine Empfehlung | U18: Sanierungswunsch Ja / Nein Annahme Standardwärmedämmung EPS/XPS WLG (030) U-Wert gemäß BEG EM 0,25 [W/m²K]
B19: HT | C19: = | D19: U | E19: * | F19: A | H19: =_xlfn.CEILING.MATH(H23,0.02) -> 0.1 | K19: ='Kat. 1 U-Wert'!F102 -> 0.25 | M19: =K7 -> 1 | P19: =AB8 -> 0.03
B20: =D20*F20 -> 19.25 | C20: = | D20: =K19 -> 0.25 | E20: * | F20: =M4 -> 77 | H20: einzubauende Dämmstärke | K20: gemäß BEG EM | M20: Bestand | P20: Dämmung Neu | R20: Unterste Geschossdecke nicht gedämmt | S20: Empfehlung Dämmung | U20: aus Datenstufe 2 Bestandsaufnahme Annahme Standardwärmedämmung EPS/XPS WLG (030) U-Wert gemäß BEG EM 0,25 [W/m²K]
H22: dDä,NEU | J22: = | K22: (1/UNEU | M22: - | N22: 1/UVORH) | P22: * | Q22: λDä,NEU | R22: Dämmung >40 Jahre Bewertung als sanierungsbedürftig | S22: Empfehlung Dämmungstausch | U22: aus Datenstufe 2 Bestandsaufnahme Annahme Standardwärmedämmung EPS/XPS WLG (030) U-Wert gemäß BEG EM 0,25 [W/m²K]
H23: =(K23-N23)*Q23 -> 0.09 | J23: = | K23: =1/K19 -> 4 | M23: - | N23: =1/K7 -> 1 | P23: * | Q23: =P19 -> 0.03
B25: Platzhalter für Kosten

Sheet Heizung
A4: Heizungssystem - Bestand
A5: Endenergie-Aufwandszahl e th,ges | B5: System | D5: zentral
D6: zentral mit Zusatzheizung
D7: dezentral
B9: Jahresverbrauch Wertermittlung (kWh/a) | D9: Nutzereingabe in kWh/a
F11: Umbau auf Flächenheizung erwünscht? Ja/Nein | G11: Brennstofflager-fläche vorhanden Ja/Nein | H11: Sanierungsmaßnahme Bsp
B12: Wärmeerzeugung zentral | C12: Baujahr über LOD oder Alterseingabe (gemäß Kat.2 Heizung) | D12: Nutzereingabe der Heizungsanlage
C14: Öl | D14: Standardkessel | F14: X | G14: - | H14: Wärmepumpe(Luft-Wasser)
D15: Niedertemperaturkessel | F15: - | G15: X | H15: Biomasse (kein Lager = Fernwärme)
D16: Brennwertkessel | F16: - | G16: - | H16: Gas-Hybridheizung / Fernwärme
C18: Erdgas | D18: Standardkessel | F18: - | G18: - | H18: Gas-Hybridheizung / Fernwärme
D19: Niedertemperaturkessel | F19: - | G19: X | H19: Biomasse (kein Lager = Fernwärme)
D20: Brennwertkessel | F20: X | H20: Wärmepumpe
C22: Biomasse | D22: Pellets | F22: - | G22: - | H22: keine Sanierungsempfehlung
D23: Scheitholz | F23: - | G23: - | H23: keine Sanierungsempfehlung
C25: Strom | D25: Luft-Wasser Wärmepumpe | F25: - | G25: - | H25: keine Sanierungsempfehlung
D26: Wasser-Wasser Wärmepumpe | F26: - | G26: - | H26: keine Sanierungsempfehlung
D27: Sole-Wasser Wärmepumpe Sonden | F27: - | G27: - | H27: keine Sanierungsempfehlung
D28: Sole-Wasser Wärmepumpe Erdkollektor | F28: - | G28: - | H28: keine Sanierungsempfehlung
D29: Stromdirektheizung | F29: X | G29: - | H29: Wärmepumpe
C31: Fernwärme | H31: keine Sanierungsempfehlung
B33: Zusatzheizung | C33: Sonne | D33: Solarthermie WWB | F33: - | H33: keine Sanierungsempfehlung
D34: Solarthermie WWB und Heizung | F34: - | H34: keine Sanierungsempfehlung
C36: Biomasse | D36: Pellets | F36: - | H36: keine Sanierungsempfehlung
D37: Scheitholz | F37: - | H37: keine Sanierungsempfehlung
B39: Heizflächenart | C39: Heizkörper | F39: X | H39: Umbau zur Flächenheizung
C40: Flächenheizung (Fußboden-, Wand-, Deckenheizung) | F40: -
C42: Einzelöfen | F42: -
B43: Zusatzimfomation für Sanierungsempfehlung
C45: Photovoltaik-Anlage vorhanden
C46: Photovoltaik-Anlage möglich | D46: Solarkataster
C48: Fernwärmeanschluss möglich | D48: Gebietszuordnung
C50: Gasanschluss vorhanden | D50: Gebietszuordnung
C52: Umstellung auf Flächenheizung geplant
C54: Brennstofflagerfläche im Gebäude vorhanden
C55: Brennstofflagerfläche im Gebäude möglich

Sheet Berechnungen
B2: beheiztes Gebäudevolumen
B3: Ve | C3: = | D3: Grundfläche | E3: * | F3: Geschosshöhen | N3: Ve beheiztes Gebäudevolumen über LOD (Grundfläche x Höhe)
B4: [m³] | D4: [m²] | F4: [m]
B5: =D5*F5 -> 454.3 | C5: = | D5: 77 | E5: * | F5: 5.9
B7: beheiztes Luftvolumen
B8: VL | C8: = | D8: 0.76 | E8: * | F8: Ve | N8: VL beheiztes Luftvolumen [bis zu 3 Vollgeschosse (0,76 * Ve) oder übrige Fälle (0,80 * Ve) ]
B9: [m³] | D9: Fixwert | F9: [m³]
B10: =D10*F10 -> 345.268 | C10: = | D10: 0.76 | E10: * | F10: =B5 -> 454.3
B12: Nutzfläche über beheiztes Gebäudevolumen
B13: AN | C13: = | D13: 0.32 | E13: * | F13: Ve | N13: AN Nutzfläche nach GEG (0,32 * Ve )
B14: [m²] | D14: Fixwert | F14: [m³]
B15: =D15*F15 -> 145.376 | C15: = | D15: 0.32 | E15: * | F15: =F10 -> 454.3
B17: Nettogrundfläche EFH über Nutzfläche
B18: ANGF | C18: = | D18: 1,1/1,35 | E18: * | F18: AN | N18: ANGF EFH mit beheiztem Keller (1,1/1,35 * AN)
B19: [m²] | D19: Fixwert | F19: [m²] | N19: Abhängig vom Bestandsgebäude
B20: =D20*F20 -> 118.45452 | C20: = | D20: =1.1/1.35 -> 0.81481481 | E20: * | F20: =B15 -> 145.376
B22: Nettogrundfläche MFH über Nutzfläche
B23: ANGF | C23: = | D23: 1,1/1,2 | E23: * | F23: AN | N23: ANGF EFH ohne beheiztem Keller sowie MFH (1,1/1,2 * AN)
B24: [m²] | D24: Fixwert | F24: [m²] | N24: Abhängig vom Bestandsgebäude
B25: =D25*F25 -> 133.26133 | C25: = | D25: =1.1/1.2 -> 0.91666667 | E25: * | F25: =B15 -> 145.376
B27: Nettgrundfläche über Wohnfläche
B28: ANGF | C28: = | D28: 1.1 | E28: * | F28: AWohn | N28: ANGF (1,1 * Awohn)
B29: [m²] | D29: Fixwert | F29: [m²]
B30: =D30*F30 -> 154 | C30: = | D30: 1.1 | E30: * | F30: 140
B32: Gesamtluftwechsel ohne mech. Lüftung (Lüftungswärmeverlust)
B33: HV | C33: = | D33: n | E33: * | F33: 0.34 | G33: * | H33: VL | N33: HV Gesamtluftwechsel ohne mechanische Lüftung (Infiltration+Fenster)
B34: [W/K] | D34: [h-1] | F34: Fixwert [Wh/m³K] | H34: [m³] | N34: ρ * Cp = 0,34 Produkt aus Dichte und spez. Wärmekapazität von Luft [Wh/m³K]
B35: =D35*F35*H35 -> 92.738985 | C35: = | D35: 0.79 | E35: * | F35: 0.34 | G35: * | H35: =B10 -> 345.268 | N35: n = ninf + nwin (Kategorie 3 Gebäudebestand n = 0,79)
B37: Gesamtwärmeverlust
B38: H | C38: = | D38: HV | E38: + | F38: HT | N38: HV = Lüftungswärmeverlust
B39: [W/K] | D39: [W/K] | F39: [W/K] | N39: HT = Tranmissionswärmeverlust aller Bauteile inkl Wärmebrücken
B40: =D40+F40 -> 610.73898 | C40: = | D40: =B35 -> 92.738985 | E40: + | F40: =ROUND(Grobkonzept!U74,0) -> 518
B42: Gesamt-Lüftungswärmesenken ohne mech. Lüftung
B43: QV | C43: = | D43: HV | E43: * | F43: Θi | G43: - | H43: Θe | I43: * | J43: 0.001 | K43: * | L43: t | N43: QV Gesamt-Lüftungswärmsenken | Q43: t = 24 Stunden pro Tag [h/d]
B44: [kWh/d] | D44: [W/K] | F44: [°C] | H44: [°C] | J44: Fixwert [kW] | L44: [h/d] | N44: Θi = Bilanz-Innentemperatur Gebäudezone [20°C] | R44: Θe = durchschnittliche monatliche Außentemperatur [°C]
B45: QV [kWh/a] | C45: = | D45: HV [W/K] | E45: * | F45: HDD [Kd/a] | I45: * | J45: 24/1000 [Fixwert] | M45: <-- | N45: angepasste Formel zur weiteren Berechnung
B46: =D46*F46*J46 -> 8070.5174 | C46: = | D46: =B35 -> 92.738985 | E46: * | F46: 3626 | I46: * | J46: 0.024
B48: Interne Wärmequellen über Nettogrundfläche
B49: Ql,source | C49: = | D49: ql | E49: * | F49: ANGF | G49: * | H49: 0.001 | N49: Interne Wärmequellen mit ql = 45Wh/m²d (EFH) oder 90 Wh/m²d (MFH)
B50: [kWh] | D50: [W/m²d] | F50: [m²] | H50: Fixwert [kW]
...

Sheet Kat. 1 U-Wert
A1: Quelle: Bundesanzeiger - Bekanntmachung der Regeln zur Datenaufnahme und Datenverwendung im Wohngebäudebestand vom 08. Oktober 2020
M3: grau = wird nicht genutzt
A5: Tabelle 2: Pauschalwerte für den Wärmedurchgangskoeffizienten
A6: Bauteil | B6: Konstruktion | C6: Baualtersklassen
C7: bis 1918 | D7: 1919 bis 1948 | E7: 1949 bis 1957 | F7: 1958 bis 1968 | G7: 1969 bis 1978 | H7: 1979 bis 1983 | I7: 1984 bis 1994 | J7: 1995 bis 2001 | K7: 2002 bis 2006
C8: Pauschalwerte für den Wärmedurchgangskoeffizienten in W/(m²*K)
A9: Dach | B9: Massive Konstruktion | C9: 2.1 | D9: 2.1 | E9: 2.1 | F9: 1.3 | G9: 1.3 | H9: 0.6 | I9: 0.4 | J9: 0.3 | K9: 0.2 | M9: Empfehlung Komplettsanierung
B10: Holzkonstruktion | C10: 2.6 | D10: 1.4 | E10: 1.4 | F10: 1.4 | G10: 0.8 | H10: 0.7 | I10: 0.5 | J10: 0.3 | K10: 0.2
A12: Oberste Geschossdecke | B12: Massive Decke | C12: 2.1 | D12: 2.1 | E12: 2.1 | F12: 2.1 | G12: 0.6 | H12: 0.6 | I12: 0.3 | J12: 0.3 | K12: 0.2
B13: Holzbalkendecke | C13: 1 | D13: 1 | E13: 0.8 | F13: 0.7 | G13: 0.6 | H13: 0.4 | I13: 0.3 | J13: 0.3 | K13: 0.3
A15: Außenwand massive Konstruktion | B15: Zweischalige Wandaufbauten | C15: 1.3 | D15: 1.3 | E15: 1.3 | F15: 1.4 | G15: 1 | H15: 0.8 | I15: 0.6 | J15: 0.5 | K15: 0.4
B16: Zweischalige Wand- aufbauten mit Dämmung | C16: keine Angabe | D16: keine Angabe | E16: 1 | F16: 0.9 | G16: 0.9 | H16: 0.7 | I16: 0.5 | J16: 0.5 | K16: 0.4
B17: Massivwand aus Vollziegel bis 20cm Wandstärke | C17: 2.8 | D17: 2.8 | E17: 2.8 | F17: keine Angabe | G17: keine Angabe | H17: keine Angabe | I17: keine Angabe | J17: keine Angabe | K17: keine Angabe
B18: Wie vorstehend, jedoch 20 bis 30cm Wandstärke | C18: 1.8 | D18: 1.8 | E18: 1.8 | F18: keine Angabe | G18: keine Angabe | H18: keine Angabe | I18: keine Angabe | J18: keine Angabe | K18: keine Angabe
B19: Wie vorstehend, jedoch über 30cm Wandstärke | C19: 1.5 | D19: 1.5 | E19: 1.5 | F19: keine Angabe | G19: keine Angabe | H19: keine Angabe | I19: keine Angabe | J19: keine Angabe | K19: keine Angabe
B20: Massivwand aus Hochlochziegel | C20: 1.4 | D20: 1.4 | E20: 1.4 | F20: 1.4 | G20: 1 | H20: 0.8 | I20: 0.6 | J20: 0.5 | K20: 0.4
B21: Sonstige massive Wandaufbauten bis 20cm Wandstärke | C21: 3 | D21: 3 | E21: 3 | F21: 1.4 | G21: 1 | H21: 0.8 | I21: 0.7 | J21: 0.7 | K21: 0.4
B22: Sonstige Wandaufbauten über 20cm Wandstärke | C22: 2.2 | D22: 2.2 | E22: 2.2 | F22: 1.4 | G22: 1 | H22: 0.8 | I22: 0.6 | J22: 0.5 | K22: 0.4
A24: Außenwand Holzkonstruktion (Fachwerk, Fertighaus) | B24: Massivholzwand, Holzrahmen oder Holztafelwand | C24: 0.5 | D24: 0.5 | E24: 0.5 | F24: 0.5 | G24: 0.5 | H24: 0.5 | I24: 0.4 | J24: 0.4 | K24: 0.3
B25: Sonstige Holzkonstruktion | C25: 2 | D25: 2 | E25: 1.5 | F25: 1.4 | G25: 0.6 | H25: 0.5 | I25: 0.4 | J25: 0.4 | K25: 0.3
A27: Sonstige Bauteile gg. Erdreich oder unbeheizte Räume | B27: Kellerdecke Stahlbeton massiv | C27: 1.6 | D27: 1.6 | E27: 2.3 | F27: 1 | G27: 1 | H27: 0.8 | I27: 0.6 | J27: 0.6 | K27: 0.5
B28: Kellerdecke als Holzbalkendecke | C28: 1 | D28: 1 | E28: 1 | F28: 0.8 | G28: 0.6 | H28: 0.6 | I28: 0.4 | J28: 0.4 | K28: 0.4
B29: Boden gegen Erdreich, Stahlbeton massiv | C29: 1.6 | D29: 1.6 | E29: 2.3 | F29: 1.2 | G29: 1.2 | H29: 0.8 | I29: 0.6 | J29: 0.6 | K29: 0.5
A31: Türen | B31: Im Wesentlichen aus Metall | C31: 4
B32: Im Wesentlichen aus Holz, Holzwerkstoffen oder Kunststoff | C32: 2.9
A34: Bauteil | B34: Konstruktion | F34: Eigen- schaft | G34: Baualtersklasse
G35: bis 1978 | H35: 1979 bis 1983 | I35: 1984 bis 1994 | J35: 1995 bis 2001 | K35: ab 2002
A38: Fenster, Fenstertüren | B38: Holzfenster, einfach verglast | F38: UW | G38: 5 | H38: keine Angabe | I38: keine Angabe | J38: keine Angabe | K38: keine Angabe
F39: Glas | G39: einfach | H39: keine Angabe | I39: keine Angabe | J39: keine Angabe | K39: keine Angabe
B40: Holzfenster, zwei Scheiben | F40: UW | G40: 2.7 | H40: 2.7 | I40: 2.7 | J40: 1.6 | K40: 1.5
F41: Glas | G41: zweifach | H41: zweifach | I41: zweifach | J41: MSIV 2 | K41: MSIV 2
B42: Kunststofffenster, Isolierverglasung | F42: UW | G42: 3 | H42: 3 | I42: 3 | J42: 1.9 | K42: 1.5
F43: Glas | G43: zweifach | H43: zweifach | I43: zweifach | J43: MSIV 2 | K43: MSIV 2
B44: Aluminium- oder Stahlfenster, Isolierverglasung | F44: UW | G44: 4.3 | H44: 4.3 | I44: 3.2 | J44: 1.9 | K44: 1.5
F45: Glas | G45: zweifach | H45: zweifach | I45: zweifach | J45: MSIV 2 | K45: MSIV 2
A46: MSIV 2 = Mehrscheibenisolierverglasung
A49: Tabelle: Wärmeübergangswiderstände (R-Werte Rsi und Rse) für an Außenluft grenzende Räume
A50: Wärmeübergangswiderstand | C50: aufwärts | E50: horizontal | G50: abwärts
A51: Rsi | C51: 0.1 | E51: 0.13 | G51: 0.17
A52: Rse | C52: 0.04 | E52: 0.04 | G52: 0.04
...

Sheet Kat. 2 Heizung
A1: Quelle: Bundesanzeiger - Bekanntmachung der Regeln zur Datenaufnahme und Datenverwendung im Wohngebäudebestand vom 08. Oktober 2020
B3: Endenergie-Aufwandszahl | C3: Durchschnittswerte für die Raumheizung und Warmwasserbereitung (ohne Hilfsenergie) | I3: * | J3: Raumtemperaturregelung Flächenheizung | K3: oder | L3: Raumtemperaturregelung freie Heizflächen
D4: Heizkreistemperatur | E4: Baualter | F4: Aufwandszahl e AN150 [m²] | G4: Aufwandszahl e AN 500 [m²] | H4: Aufwandszahl e AN 2500 [m²]
J5: eh,ce,0 + ∆eh,ce,1 | L5: eh,ce,0 + ∆eh,ce,1
C6: Standardkessel (auch Holzkessel) | D6: 70/55°C | E6: bis 1986 | F6: 1.47 | G6: 1.36 | H6: 1.28 | J6: =F33+F43 -> 1.128 | L6: =N33+M44 -> 1.128
E7: 1987 - 1994 | F7: 1.34 | G7: 1.26 | H7: 1.19 | J7: =F35+F43 -> 1.104 | L7: =N35+M44 -> 1.104
E8: ab 1995 | F8: 1.33 | G8: 1.23 | H8: 1.16 | J8: =F36+F43 -> 1.063 | L8: =N36+M44 -> 1.063
C9: Niedertemperaturkessel Öl / Gas | D9: 70/55°C | E9: bis 1986 | F9: 1.24 | G9: 1.21 | H9: 1.18 | J9: =F35+F43 -> 1.104 | L9: =N35+M44 -> 1.104
E10: 1987 bis 1994 | F10: 1.19 | G10: 1.15 | H10: 1.13 | J10: =F36+F43 -> 1.063 | L10: =N36+M44 -> 1.063
E11: ab 1995 | F11: 1.14 | G11: 1.11 | H11: 1.09 | J11: =F37+F43 -> 1.063 | L11: =N37+M44 -> 1.063
C12: Brennwertkessel | D12: 70/55°C | E12: bis 1986 | F12: 1.11 | G12: 1.09 | H12: 1.07 | J12: =F35+F43 -> 1.104 | L12: =N35+M44 -> 1.104
E13: 1987 bis 1994 | F13: 1.09 | G13: 1.06 | H13: 1.04 | J13: =F36+F43 -> 1.063 | L13: =N36+M44 -> 1.063
E14: ab 1995 | F14: 1.07 | G14: 1.05 | H14: 1.04 | J14: =F36+F43 -> 1.063 | L14: =N36+M44 -> 1.063 | N14: Testgebäude 1
C15: Brennwertkessel (verbessert) | D15: 55/45°C | E15: ab 1999 | F15: 0.99 | G15: 0.98 | H15: 0.97 | J15: =F37+F43 -> 1.063 | L15: =N37+M45 -> 1.057
C16: Fernwärme | D16: alle | E16: alle | F16: 1.02 | G16: 1.02 | H16: 1.02 | J16: =F37+F43 -> 1.063 | L16: =N37+M45 -> 1.057
C17: Elektrowärmepumpe, Außenluft (Elektrisch betriebene Luft/Wasser- Wärmepumpe) | D17: 55/45°C | E17: 1979 bis 1994 | F17: 0.45 | G17: 0.45 | H17: 0.45 | J17: =F36+F43 -> 1.063 | L17: =N36+M45 -> 1.057
E18: ab 1995 | F18: 0.43 | G18: 0.43 | H18: 0.43 | J18: =F38+F43 -> 1.051 | L18: =N38+M45 -> 1.045
D19: <40°C | E19: 1979 bis 1994 | F19: 0.4 | G19: 0.4 | H19: 0.4 | J19: =F37+F43 -> 1.063 | L19: =N37+M46 -> 1.054
E20: ab 1995 | F20: 0.38 | G20: 0.38 | H20: 0.38 | J20: =F38+F43 -> 1.051 | L20: =N38+M46 -> 1.042
C21: Elektrowärmepumpe, Erdreich/Grundwasser (Elektrisch betriebene Sole/Wasser-Wärmepumpe; Wasser/Wasser-Wärmepumpe) | D21: 55/45°C | E21: 1979 bis 1994 | F21: 0.36 | G21: 0.36 | H21: 0.36 | J21: =F36+F43 -> 1.063 | L21: =N36+M45 -> 1.057
E22: ab 1995 | F22: 0.3 | G22: 0.3 | H22: 0.3 | J22: =F38+F43 -> 1.051 | L22: =N38+M45 -> 1.045
D23: <40°C | E23: 1979 bis 1994 | F23: 0.32 | G23: 0.32 | H23: 0.32 | J23: =F37+F43 -> 1.063 | L23: =N36+M46 -> 1.054
E24: ab 1995 | F24: 0.27 | G24: 0.27 | H24: 0.27 | J24: =F38+F43 -> 1.051 | L24: =N38+M46 -> 1.042
C25: Ölbefeuerte Einzelöfen | E25: alle | F25: 1.4 | G25: 1.4 | H25: - | J25: - | L25: -
C26: Gasraumheizer | E26: alle | F26: 1.47 | G26: 1.47 | H26: - | J26: - | L26: -
C27: Elektro-Direktheizgerät | E27: alle | F27: 1.02 | G27: 1.02 | H27: - | J27: - | L27: -
B30: Tabelle 22 - Aufwandszahl für bauteilintegrierten Heizflächen (Flächenheizungen); lichte Raumhöhe ≤ 4m | H30: Aufwandszahl für freie Heizflächen - Raumhöhe ≤ 4m
B31: Einflussparameter | F31: eh,ce,0 | H31: Einflussparameter | M31: eh,ce,0
B32: Raumtemperaturregelung | C32: ungeregelt, mit zentraler Zulauftemperaturregelung | F32: 1.149 | H32: Raumtemperaturregelung | I32: ungeregelt, mit zentraler Zulauftemperaturregelung | N32: 1.149
C33: Führungsraumregelung- oder Ein-Rohr-Heizung | F33: 1.107 | I33: Führungsraumregelung- oder Ein-Rohr-Heizung | N33: 1.107
C34: Raumtemperaturregelung (elektromechanisch/elektronisch) | F34: 1.095 | I34: Raumtemperaturregelung (elektromechanisch/elektronisch) | N34: 1.095
C35: P-Regler (vor 1988) | F35: 1.083 | I35: P-Regler (vor 1988) | N35: 1.083
C36: P-Regler, 2-Punkt-Regler (Hysterese ≤ 0,5K | F36: 1.042 | I36: P-Reglera | N36: 1.042
C37: PI-Reglera | F37: 1.042 | I37: PI-Reglera | N37: 1.042
C38: PID-Regler (mit Optimierungsfunktion, z.B. Anwesenheits- management, adaptivem Regler)a | F38: 1.03 | I38: PID-Regler (mit Optimierungsfunktion, z.B. Anwesenheits- management, adaptivem Regler)a | N38: 1.03
B40: Zu- / Abschlag auf Aufwandszahl eh,ce,0 | H40: Zu- / Abschlag auf Aufwandszahl eh,ce,0
F41: ∆eh,ce,1 | M41: ∆eh,ce,1
B42: System | C42: Fußbodenheizung | H42: Übertemperatur | I42: Zwei-Rohr-Heizung und Ein-Rohr-Heizung, erneuert
C43:  Nasssystem | F43: 0.021 | I43: 60K (z.B. 90°C / 70°C) | M43: 0.036
C44:  Trockensystem | F44: 0.012 | I44: 42,5K (z.B. 70°C / 55°C) | M44: 0.021
...

Sheet Formeln
A3: Jahres-Heizwärmebedarf kWh/a | D3: [Gradtagsfaktor x (Transmissionswärmeverlust + Lüftungswärmeverlust)] - [Nutzungsgrad interner Gewinne x (solare Gewinne + interne Gewinne)]
A5: Interne Wärmegewinne W/m² | D5: 5 x Nutzfläche x Länge der Heizperiode x 0,024 (Länge der Heizperiode im Durchschnitt 185 Tage)
A7: Solare Gewinne | D7: ∑ (Einstrahlung x Energiedurchlassgrad der Fenster x Fläche X Korrekturfaktoren) pro Himmelsrichtung
A9: Wärmebedarf | D9: Transmissionswärmeverlust + Lüftungswärmeverlust
A11: Transmissionswärmeverlust HT | D11: ∑ (Korrekturfaktor x U-Wert x Bauteilfläche) + (Wärmebrückenzuschlag x Hüllfläche des Gebäudes) | S11: Absoluter Wert
A13: spezifischer Transmissionswärmeverlust HT' | D13: Transmissionswärmeverlust HT / thermische Hüllfläche | S13: Flächenbezogen
A15: Nutzfläche ANG | D15: Gebäudevolumen x 0,32
A17: Gradtagszahl Kd/a | D17: Außentemperatur unter einer festgelegten Heizgrenztemperatur (regional) (Bsp.: dena-Energiepass)
A19: Gradtagsfaktor kKh | D19: Gradtagszahl x Faktor 0,024
A21: Lüftungswärmetransferkoeffizient HV [W/K] | D21: 0,34 x Luftwechselrate x beheiztes Luftvolumen (Luftwechselrate aus DIN 18599 Tabelle 12 - 14)
A26: Kleinbuchstaben beziehen sich auf m² / Großbuchstaben beziehen sich auf den Jahreswert
