Workbook

Sheet Grobkonzept
H1: Nutzereingaben | AB1: Datenstufe 1 | AD1: Datenstufe 2 | AH1: Datenstufe 3
H2: Gebäude Allgemein
O3: Baujahr | AB3: keine | AD3: Eingabe | AH3: Eingabe
O4: Bewohner | AB4: keine | AD4: Eingabe | AH4: Eingabe
O5: Sanierungszustand | V5: (schlecht mittel gut) | AB5: keine | AD5: keine | AH5: Eingabe
H7: Dach
O8: Alter des Bauteils | AB8: keine | AD8: Eingabe | AH8: Eingabe
O9: Fläche (Hüllflächenanteil) | AB9: keine | AD9: Eingabe | AH9: Eingabe
O10: Dachform | AB10: keine | AD10: Eingabe | AH10: Eingabe
O11: Dämmung vorhanden | AB11: keine | AD11: Eingabe | AH11: Eingabe
O12: Dämmschichtdicke | AB12: keine | AD12: keine | AH12: Eingabe
O13: Wärmeleitgruppe | AB13: keine | AD13: keine | AH13: Eingabe
O14: U-Wert Bestand | V14: ggf. mit Link zu einem U-Wertrechenr | AB14: keine | AD14: keine | AH14: Eingabe
H16: Oberste Geschossdecke (OGD)
O17: Alter des Bauteils | AB17: keine | AD17: Eingabe | AH17: Eingabe
O18: Fläche (Hüllflächenanteil) | AB18: keine | AD18: Eingabe | AH18: Eingabe
O19: Dämmung vorhanden | AB19: keine | AD19: Eingabe | AH19: Eingabe
O20: Dämmschichtdicke | AB20: keine | AD20: keine | AH20: Eingabe
O21: Wärmeleitgruppe | AB21: keine | AD21: keine | AH21: Eingabe
O22: U-Wert Bestand | AB22: keine | AD22: keine | AH22: Eingabe
H24: Außenwand
O25: Alter des Bauteils | AB25: keine | AD25: Eingabe | AH25: Eingabe
O26: Fläche (Hüllflächenanteil) | AB26: keine | AD26: Eingabe | AH26: Eingabe
O27: Dämmung vorhanden | AB27: keine | AD27: Eingabe | AH27: Eingabe
O28: Dämmschichtdicke | AB28: keine | AD28: keine | AH28: Eingabe
O29: Wärmeleitgruppe | AB29: keine | AD29: keine | AH29: Eingabe
O30: U-Wert Bestand | AB30: keine | AD30: keine | AH30: Eingabe
H32: Fenster/Türen
O33: Alter des Bauteils | AB33: keine | AD33: Eingabe | AH33: Eingabe
O34: Fläche (Hüllflächenanteil) | AB34: keine | AD34: Eingabe | AH34: Eingabe
O35: U-Wert Bestand | AB35: keine | AD35: keine | AH35: Eingabe
H37: Unterste Geschossdecek (UGD)
O38: Alter des Bauteils | AB38: keine | AD38: Eingabe | AH38: Eingabe
O39: Fläche (Hüllflächenanteil) | AB39: keine | AD39: Eingabe | AH39: Eingabe
O40: Dämmung vorhanden | AB40: keine | AD40: Eingabe | AH40: Eingabe
O41: Dämmschichtdicke | AB41: keine | AD41: keine | AH41: Eingabe
O42: Wärmeleitgruppe | AB42: keine | AD42: keine | AH42: Eingabe
O43: U-Wert Bestand | AB43: keine | AD43: keine | AH43: Eingabe
A46: Bestandsanalyse | B46: Weiterberechnung der für den Nutzer relevante Ergebnisse
AB47: Datenstufe 1 | AD47: Datenstufe 2 | AH47: Datenstufe 3
...

Sheet Dach-Fenster
AE2: Datenstufe 1 | AG2: Datenstufe 2
B3: absolute Brennstoffkosten | C3: spez. Brennstoffkosten | D3: Brennstoffverbrauch | E3: Erzeugerwirkungsgrad | G3: Heizwärmebedarf | H3: umfassungsflächenbezogener Transmissionswärmeverlust | P3: Dach | X3: Fläche A [m²] | AE3: LOD oder Nutzereingabe der Fläche [m²] | AG3: Nutzereingabe der Fläche | AK3: Beispiel: | AM3: 0 | AN3: [m²]
G4: QH [kWh/a] | Y4: A = | Z4: =AM3 -> 0 | AG4: Dachfläche - Dachfensterfläche: | AM4: =AM3-AM15 -> 0 | AN4: [m²]
H5: HT' [W/m²K] | P5: HT [W/K] | X5: U-Wert [W/m²K] | AE5: Baujahr über LOD oder Alterseingabe (gemäß Kat.1 U-Wert) | AG5: Berechnung U-Wert über Nutzereingabe der Bauteilschichten | AR5: Dropdown-Menü entweder oder
Q6: HT | R6: = | S6: U | T6: * | U6: A | X6: U | Y6: = | Z6: (1 | AA6: / | AB6: RT) | AE6: Dachraum beheizt Ja / Nein | AG6: Zwischensparren Dicke | AK6: 0.2 | AL6: [m] | AM6: Festgelegt WLG | AO6: 0.04
Q7: =#REF!*S7*U7 -> #REF! | R7: = | S7: =ROUND(X8,3) -> 0.254 | T7: * | U7: =Z4 -> 0 | X7: =ROUND(Z7/AB7,3) -> 0.195 | Y7: = | Z7: 1 | AA7: / | AB7: =AG10 -> 5.14 | AE7: ='Kat. 1 U-Wert'!B6 -> Massive Konstruktion | AF7: Flachdach | AG7: Aufdachdämmung Dicke | AK7: 0.2 | AL7: [m] | AM7: Festgelegt WLG | AO7: 0.04
X8: =Z8*AB8 -> 0.2535 | Y8: = | Z8: =X7 -> 0.195 | AA8: * | AB8: 1.3 | AE8: ='Kat. 1 U-Wert'!B7 -> Holzkonstruktion | AF8: Satteldach | AG8: Stahlbetondecke 25cm mit R-Wert 0,11
AG9: (RT,Zwischensparren | AH9: = | AI9: Rsi | AJ9: + | AK9: ∑R (Dicke [m] | AL9: / | AM9: λ [W/mK]) | AN9: + | AO9: Rse) | AP9: * | AQ9: Minderungsfaktor
AG10: =AI10+(AK10/AM10)+AO10 -> 5.14 | AH10: = | AI10: ='Kat. 1 U-Wert'!C48 -> 0.1 | AJ10: + | AK10: =AK6 -> 0.2 | AL10: / | AM10: =AO6 -> 0.04 | AN10: + | AO10: ='Kat. 1 U-Wert'!C49 -> 0.04 | AP10: * | AQ10: 0.3
X11: =ROUND(Z11/AB11,3) -> 0.191 | Y11: = | Z11: 1 | AA11: / | AB11: =AG12 -> 5.2486957 | AG11: RT,Aufsparren | AH11: = | AI11: Rsi | AJ11: + | AK11: ∑R (Dicke [m] | AL11: / | AM11: λ [W/mK]) | AN11: + | AO11: Rse
X12: kein Korrekturfaktor | AG12: =AI12+(AK12/AM12+AK13/AM13)+AO12 -> 5.2486957 | AH12: = | AI12: ='Kat. 1 U-Wert'!C48 -> 0.1 | AJ12: + | AK12: =AK7 -> 0.2 | AL12: / | AM12: =AO7 -> 0.04 | AN12: + | AO12: ='Kat. 1 U-Wert'!C49 -> 0.04
AK13: 0.25 | AL13: / | AM13: 2.3
P15: Dachfenster | X15: Fläche A [m²] | AE15: LOD oder Nutzereingabe der Fläche [m²] | AG15: Nutzereingabe der Fläche | AK15: Beispiel: | AM15: 0 | AN15: [m²]
Q16: HT | R16: = | S16: F | T16: * | U16: U | V16: * | W16: A | X16: A | Y16: = | Z16: =AM15 -> 0
Q17: =S17*U17*W17 -> 0 | R17: = | S17: 0.93 | T17: * | U17: =Z18 -> 2 | V17: * | W17: =Z16 -> 0 | X17: U-Wert [W/m²K] | AE17: Baujahr über LOD oder Alterseingabe (U-Wert gemäß Kat. 1) | AG17: Angabe des U-Werts über Nutzereingabe | AM17: Beispiel: | AN17: 2 | AO17: [W/m²K]
X18: U | Y18: = | Z18: =AN17 -> 2 | AE18: ='Kat. 1 U-Wert'!B37 -> Holzfenster, zwei Scheiben | AF18: (> 40 Jahre) | AG18: oder Alterseingabe gemäß Kat.1 U-Wert über
AE19: ='Kat. 1 U-Wert'!B39 -> Kunststofffenster, Isolierverglasung | AF19: (< 40 Jahre) | AG19: Rahmenart (Holz, Kunststoff; Aluminium/Stahl) und
AG20: Glasart (Einfach; Zweifach; Dreifach)
A23: Sanierungsempfehlung Gebäudehülle
O24: Dach saniert | U24: Dicke Dämmung NEU | X24: U-Wert NEU | Z24: U-Wert VORH | AC24: Lamda-Wert | AE24: Sanierungsempfehlung über Baujahr nach Gebiet oder Nutzereingabe
O25: HT [W/K] | U25: [m] | X25: [W/m²K] | Z25: [W/m²K] | AC25: λ [W/mK]) | AE25: Oberste Geschossdecke gedämmt | AF25: keine Empfehlung | AG25: Sanierungswunsch Ja / Nein Annahme Standardwärmedämmung Mineralwolle WLG (035) U-Wert gemäß BEG EM 0,14 [W/m²K]
O26: HT | P26: = | Q26: U | R26: * | S26: A | U26: =ROUNDUP(U30,2) -> #DIV/0! | X26: ='Kat. 1 U-Wert'!F93 -> 0.14 | Z26: =Y14 -> 0 | AC26: =AO7 -> 0.04
O27: =Q27*S27 -> 0 | P27: = | Q27: =X26 -> 0.14 | R27: * | S27: =Z4 -> 0 | U27: einzubauende Dämmstärke | X27: gemäß BEG EM | Z27: Bestand | AC27: Dämmung Neu | AE27: Oberste Geschossdecke nicht gedämmt | AF27: Empfehlung Dämmung | AG27: aus Datenstufe 2 Bestandsaufnahme Annahme Standardwärmedämmung Mineralwolle WLG (035) U-Wert gemäß BEG EM 0,14 [W/m²K]
U29: dDä,NEU | W29: = | X29: (1/UNEU | Z29: - | AA29: 1/UVORH) | AC29: * | AD29: λDä,NEU | AE29: Dämmung >40 Jahre Bewertung als sanierungsbedürftig | AF29: Komplettsanierung | AG29: aus Datenstufe 2 Bestandsaufnahme Annahme Standardwärmedämmung Mineralwolle WLG (035) U-Wert gemäß BEG EM 0,14 [W/m²K]
U30: =(X30-AA30)*AD30 -> #DIV/0! | W30: = | X30: =1/X26 -> 7.1428571 | Z30: - | AA30: =1/0 -> #DIV/0! | AC30: * | AD30: =AC26 -> 0.04
O32: Platzhalter für Kosten
O34: Dachfenster saniert | X34: U-Wert NEU | Z34: U-Wert VORH | AE34: Dachfenstertausch über Baujahr nach Gebiet oder Nutzereingabe
O35: HT [W/K] | X35: [W/m²K] | Z35: [W/m²K] | AE35: (<30 Jahre Bewertung als neueres Fenster) | AF35: keine Empfehlung | AG35: Sanierungswunsch Ja / Nein Standard-Kunststoffrahmen- oder Holzrahmenfenster U-Wert gemäß BEG EM 1,00 [W/m²K]
O36: HT | P36: = | Q36: U | R36: * | S36: A | X36: ='Kat. 1 U-Wert'!F85 -> 1 | Z36: =Z18 -> 2
O37: =Q37*S37 -> 0 | P37: = | Q37: =X36 -> 1 | R37: * | S37: =Z16 -> 0 | X37: gemäß BEG EM | Z37: Bestand | AE37: (>30 Jahre Bewertung als sanierungsbedürftig) | AF37: Dachfenstertausch | AG37: Abfrage: Standard-Kunststoffrahmen- oder Holzrahmenfenster U-Wert gemäß BEG EM 1,00 [W/m²K]
O39: Platzhalter für Kosten

Sheet OGD
AE2: Datenstufe 1 | AG2: Datenstufe 2
B3: absolute Brennstoffkosten | C3: spez. Brennstoffkosten | D3: Brennstoffverbrauch | E3: Erzeugerwirkungsgrad | G3: Heizwärmebedarf | H3: umfassungsflächenbezogener Transmissionswärmeverlust | P3: OGD | X3: Fläche A [m²] | AE3: LOD Grundfläche oder Nutzereingabe der Fläche [m²] | AG3: Nutzereingabe der Fläche | AK3: Beispiel: | AM3: 70 | AN3: [m²]
G4: QH [kWh/a] | X4: A | Y4: = | Z4: =AM3 -> 70
H5: HT' [W/m²K] | P5: HT [W/K] | X5: U-Wert [W/m²K] | AE5: Baujahr über LOD oder Alterseingabe (gemäß Kat.1 U-Wert) | AG5: Berechnung U-Wert über Nutzereingabe der Bauteilschichten
Q6: HT | R6: = | S6: U | T6: * | U6: A | X6: U | Y6: = | Z6: (1 | AA6: / | AB6: RT) | AE6: Dachraum beheizt Ja/Nein | AG6: ='Kat. 1 U-Wert'!B9 -> Massive Decke | AL6: (gemäß Kat.1 U-Wert) | AO6: ='Kat. 1 U-Wert'!F10 -> 0.7
Q7: =S7*U7 -> 49 | R7: = | S7: =X7 -> 0.7 | T7: * | U7: =Z4 -> 70 | X7: =Z7/AB7 -> 0.7 | Y7: = | Z7: 1 | AA7: / | AB7: =AK14+AM14 -> 1.4285714 | AE7: ='Kat. 1 U-Wert'!B9 -> Massive Decke | AF7: (< 60 Jahre) | AG7: ='Kat. 1 U-Wert'!B10 -> Holzbalkendecke | AL7: (gemäß Kat.1 U-Wert)
AE8: ='Kat. 1 U-Wert'!B10 -> Holzbalkendecke | AF8: (> 60 Jahre) | AG8: Dämmschichtdicke | AK8: 0 | AL8: [m] | AM8: Festgelegt WLG | AO8: 0.032
AG9: RT,Dämmung | AH9: = | AI9: Rsi | AJ9: + | AK9: ∑R (Dicke [m] | AL9: / | AM9: λ [W/mK]) | AN9: + | AO9: Rse
AG10: =AI10+(AK10/AM10)+AO10 -> 0 | AH10: = | AI10: =IF(AK8>0,'Kat. 1 U-Wert'!C48,0) -> 0 | AJ10: + | AK10: =AK8 -> 0 | AL10: / | AM10: =AO8 -> 0.032 | AN10: + | AO10: =IF(AK8>0,'Kat. 1 U-Wert'!C49,0) -> 0
AG11: RTDecke | AH11: = | AI11: 1 | AJ11: / | AK11: (gemäß Kat.1 U-Wert)
AG12: =AI12/AK12 -> 1.4285714 | AH12: = | AI12: 1 | AJ12: / | AK12: =AO6 -> 0.7
AG13: RT | AH13: = | AK13: (RTDecke | AL13: + | AM13: RT,Dämmung)
AG14: =AK14+AM14 -> 1.4285714 | AH14: = | AK14: =AG12 -> 1.4285714 | AL14: + | AM14: =AG10 -> 0
A16: Sanierungsempfehlung Gebäudehülle
O17: OGD saniert | U17: Dicke Dämmung NEU | X17: U-Wert NEU | Z17: U-Wert VORH | AC17: Lamda-Wert | AE17: Sanierungsempfehlung über Baujahr nach Gebiet oder Nutzereingabe
O18: HT [W/K] | U18: [m] | X18: [W/m²K] | Z18: [W/m²K] | AC18: λ [W/mK]) | AE18: Oberste Geschossdecke gedämmt | AF18: keine Empfehlung | AH18: Sanierungswunsch Ja / Nein Annahme Standardwärmedämmung EPS/XPS WLG (032) U-Wert gemäß BEG EM 0,14 [W/m²K]
O19: HT | P19: = | Q19: U | R19: * | S19: A | U19: =ROUNDUP(U23,2) -> 0.19 | X19: ='Kat. 1 U-Wert'!F95 -> 0.14 | Z19: =X7 -> 0.7 | AC19: =AO8 -> 0.032
O20: =Q20*S20 -> 9.8 | P20: = | Q20: =X19 -> 0.14 | R20: * | S20: =Z4 -> 70 | U20: einzubauende Dämmstärke | X20: gemäß BEG EM | Z20: Bestand | AC20: Dämmung Neu | AE20: Oberste Geschossdecke nicht gedämmt | AF20: Empfehlung Dämmung | AH20: aus Datenstufe 2 Bestandsaufnahme Annahme Standardwärmedämmung EPS/XPS WLG (032) U-Wert gemäß BEG EM 0,14 [W/m²K]
U22: dDä,NEU | W22: = | X22: (1/UNEU | Z22: - | AA22: 1/UVORH) | AC22: * | AD22: λDä,NEU | AE22: Dämmung >40 Jahre Bewertung als sanierungsbedürftig | AF22: Komplettsanierung | AH22: aus Datenstufe 2 Bestandsaufnahme Annahme Standardwärmedämmung EPS/XPS WLG (032) U-Wert gemäß BEG EM 0,14 [W/m²K]
U23: =(X23-AA23)*AD23 -> 0.18285714 | W23: = | X23: =1/X19 -> 7.1428571 | Z23: - | AA23: =1/X7 -> 1.4285714 | AC23: * | AD23: =AC19 -> 0.032
O25: Platzhalter für Kosten

Sheet AW-Fenster
AE2: Datenstufe 1 | AG2: Datenstufe 2
B3: absolute Brennstoffkosten | C3: spez. Brennstoffkosten | D3: Brennstoffverbrauch | E3: Erzeugerwirkungsgrad | G3: Heizwärmebedarf | H3: umfassungsflächenbezogener Transmissionswärmeverlust | P3: AW | X3: Fläche A [m²] | AE3: LOD (Umfang aus Grundfläche x Höhe - Fensterflächenanteil ca. 30%) (ausschließlich für unbeheizte Kellerräume) oder Nutzereingabe der Fläche [m²] | AG3: Nutzereingabe der Fläche | AK3: Beispiel: | AM3: 166.6 | AN3: [m²]
G4: QH [kWh/a] | X4: A | Y4: = | Z4: =AM4 -> 108.29 | AG4: Außenwandfläche - Fensterfläche: | AM4: =AM3-AM16 -> 108.29 | AN4: [m²]
H5: HT' [W/m²K] | X5: U-Wert [W/m²K] | AE5: Baujahr über LOD oder Alterseingabe (gemäß Kat.1 U-Wert) | AG5: Berechnung U-Wert über Nutzereingabe der Bauteilschichten
P6: HT [W/K] | X6: =ROUND(Z6/AB6,3) -> 1.4 | Y6: = | Z6: 1 | AA6: / | AB6: =AG14 -> 0.71428571 | AE6: Massivwand mit WDVS (0,20 W/m²K) | AF6: (< 20 Jahre) | AG6: Außenwandkonstruktion (gemäß Kat.1 U-Wert) | AO6: ='Kat. 1 U-Wert'!F19 -> 1.4
Q7: HT | R7: = | S7: F | T7: * | U7: U | V7: * | W7: A | AE7: ='Kat. 1 U-Wert'!B19 -> Sonstige Wandaufbauten über 20cm Wandstärke | AF7: (> 20 - 70 Jahre)
Q8: =S8*U8*W8 -> 151.606 | R8: = | S8: 1 | T8: * | U8: =X6 -> 1.4 | V8: * | W8: =Z4 -> 108.29 | AE8: ='Kat. 1 U-Wert'!B16 -> Wie vorstehend, jedoch über 30cm Wandstärke | AF8: (> 70 Jahre) | AG8: Dämmschichtdicke | AK8: 0 | AL8: [m] | AM8: Festgelegt WLG | AO8: 0.035
AG9: RT,Dämmung | AH9: = | AI9: Rsi | AJ9: + | AK9: ∑R (Dicke [m] | AL9: / | AM9: λ [W/mK]) | AN9: + | AO9: Rse
AG10: =AI10+(AK10/AM10)+AO10 -> 0 | AH10: = | AI10: =IF(AK8>0,'Kat. 1 U-Wert'!C48,0) -> 0 | AJ10: + | AK10: =AK8 -> 0 | AL10: / | AM10: =AO8 -> 0.035 | AN10: + | AO10: =IF(AK8>0,'Kat. 1 U-Wert'!C49,0) -> 0
AG11: RTAußenwand | AH11: = | AI11: 1 | AJ11: / | AK11: (gemäß Kat.1 U-Wert)
AG12: =AI12/AK12 -> 0.71428571 | AH12: = | AI12: 1 | AJ12: / | AK12: =AO6 -> 1.4
AG13: RT | AH13: = | AK13: (RTAußenwand | AL13: + | AM13: RT,Dämmung)
AG14: =AK14+AM14 -> 0.71428571 | AH14: = | AK14: =AG12 -> 0.71428571 | AL14: + | AM14: =AG10 -> 0
P16: Fenster/ Türen | X16: Fläche A [m²] | AE16: Flächenanteil LOD (35% der Gesamtaußenwandfläche) oder Nutzeingabe der Fläche | AG16: Nutzereingabe der Fläche | AK16: Beispiel: | AM16: =AM3*0.35 -> 58.31 | AN16: [m²]
X17: A | Y17: = | Z17: =AM16 -> 58.31 | AA17: m²
P18: HT [W/K] | X18: U-Wert [W/m²K] | AE18: Baujahr über LOD oder Alterseingabe (gemäß Kat.1 U-Wert) | AG18: Angabe des U-Werts über Nutzereingabe | AM18: Beispiel: | AN18: ='Kat. 1 U-Wert'!I37 -> 2.7 | AO18: [W/m²K]
Q19: HT | R19: = | S19: F | T19: * | U19: U | V19: * | W19: A | X19: U | Y19: = | Z19: =AN18 -> 2.7 | AE19: ='Kat. 1 U-Wert'!B37 -> Holzfenster, zwei Scheiben | AF19: (> 40 Jahre) | AG19: oder Alterseingabe gemäß Kat.1 U-Wert über
Q20: =S20*U20*W20 -> 146.41641 | R20: = | S20: 0.93 | T20: * | U20: =Z19 -> 2.7 | V20: * | W20: =Z17 -> 58.31 | AE20: ='Kat. 1 U-Wert'!B39 -> Kunststofffenster, Isolierverglasung | AF20: (< 40 Jahre) | AG20: Rahmenart (Holz, Kunststoff; Aluminium/Stahl) und
AG21: Glasart (Einfach; Zweifach; Dreifach)
A24: Sanierungsempfehlung Gebäudehülle
O25: AW saniert | U25: Dicke Dämmung NEU | X25: U-Wert NEU | Z25: U-Wert VORH | AC25: Lamda-Wert | AE25: Sanierungsempfehlung über Baujahr nach Gebiet oder Nutzereingabe
O26: HT [W/K] | U26: [m] | X26: [W/m²K] | Z26: [W/m²K] | AC26: λ [W/mK]) | AE26: Außenwand gedämmt | AF26: keine Empfehlung | AH26: Sanierungswunsch Ja / Nein Annahme Standardwärmedämmung EPS WLG (035) U-Wert gemäß BEG EM 0,20 [W/m²K]
O27: HT | P27: = | Q27: U | R27: * | S27: A | U27: =ROUNDUP(U31,2) -> 0.15 | X27: ='Kat. 1 U-Wert'!F64 -> 0.2 | Z27: =X6 -> 1.4 | AC27: =AO8 -> 0.035
O28: =Q28*S28 -> 21.8 | P28: = | Q28: =X27 -> 0.2 | R28: * | S28: =ROUNDUP(Z4,0) -> 109 | U28: einzubauende Dämmstärke | X28: gemäß BEG EM | Z28: Bestand | AC28: Dämmung Neu | AE28: Außenwand nicht gedämmt | AF28: Empfehlung Dämmung | AH28: aus Datenstufe 2 Bestandsaufnahme Annahme Standardwärmedämmung EPS WLG (035) U-Wert gemäß BEG EM 0,20 [W/m²K]
U30: dDä,NEU | W30: = | X30: (1/UNEU | Z30: - | AA30: 1/UVORH) | AC30: * | AD30: λDä,NEU | AE30: Dämmung >50 Jahre Bewertung als sanierungsbedürftig | AF30: Empfehlung Dämmungaustausch | AH30: aus Datenstufe 2 Bestandsaufnahme Annahme Standardwärmedämmung EPS WLG (035) U-Wert gemäß BEG EM 0,20 [W/m²K]
U31: =(X31-AA31)*AD31 -> 0.15 | W31: = | X31: =1/X27 -> 5 | Z31: - | AA31: =1/Z27 -> 0.71428571 | AC31: * | AD31: =AC27 -> 0.035
O33: Platzhalter für Kosten
O35: Fenster/ Türen saniert | X35: U-Wert NEU | Z35: U-Wert VORH | AE35: Dachfenstertausch über geschätztes Baujahr nach Gebiet oder Nutzereingabe
O36: HT [W/K] | X36: [W/m²K] | Z36: [W/m²K] | AE36: (<30 Jahre Bewertung als neueres Fenster) | AF36: keine Empfehlung | AH36: Sanierungswunsch Ja / Nein Standard-Kunststoffrahmen- oder Holzrahmenfenster U-Wert gemäß BEG EM 0,95 [W/m²K]
O37: HT | P37: = | Q37: U | R37: * | S37: A | X37: ='Kat. 1 U-Wert'!F73 -> 0.95 | Z37: =Z19 -> 2.7
O38: =Q38*S38 -> 55.3945 | P38: = | Q38: =X37 -> 0.95 | R38: * | S38: =Z17 -> 58.31 | X38: gemäß BEG EM | Z38: Bestand | AE38: (>30 Jahre Bewertung als sanierungsbedürftig) | AF38: Dachfenstertausch | AH38: Abfrage: Standard-Kunststoffrahmen- oder Holzrahmenfenster U-Wert gemäß BEG EM 0,95 [W/m²K]
O40: Platzhalter für Kosten

Sheet UGD
AE2: Datenstufe 1 | AG2: Datenstufe 2
B3: absolute Brennstoffkosten | C3: spez. Brennstoffkosten | D3: Brennstoffverbrauch | E3: Erzeugerwirkungsgrad | G3: Heizwärmebedarf | H3: umfassungsflächenbezogener Transmissionswärmeverlust | Q3: UGD | X3: Fläche A [m²] | AE3: LOD Grundfläche oder Nutzereingabe der Fläche [m²] | AG3: Nutzereingabe der Fläche | AK3: Beispiel: | AM3: 70 | AN3: [m²]
G4: QH [kWh/a] | X4: A | Y4: = | Z4: =AM3 -> 70
H5: HT' [W/m²K] | Q5: HT [W/K] | X5: U-Wert [W/m²K] | AE5: Baujahr über LOD oder Alterseingabe (gemäß Kat.1 U-Wert) | AG5: Berechnung U-Wert über Nutzereingabe der Bauteilschichten
Q6: HT | R6: = | S6: U | T6: * | U6: A | X6: U | Y6: = | Z6: (1 | AA6: / | AB6: RT) | AE6: ='Kat. 1 U-Wert'!B24 -> Kellerdecke Stahlbeton massiv | AF6: (> 60 Jahre) | AG6: ='Kat. 1 U-Wert'!B24 -> Kellerdecke Stahlbeton massiv | AL6: (gemäß Kat.1 U-Wert) | AO6: ='Kat. 1 U-Wert'!F24 -> 1
Q7: =S7*U7 -> 70 | R7: = | S7: =X7 -> 1 | T7: * | U7: =Z4 -> 70 | X7: =Z7/AB7 -> 1 | Y7: = | Z7: 1 | AA7: / | AB7: =AG10+AG12 -> 1 | AE7: ='Kat. 1 U-Wert'!B25 -> Kellerdecke als Holzbalkendecke | AF7: (< 60 Jahre) | AG7: ='Kat. 1 U-Wert'!B25 -> Kellerdecke als Holzbalkendecke | AL7: (gemäß Kat.1 U-Wert)
AE8: ='Kat. 1 U-Wert'!B26 -> Boden gegen Erdreich, Stahlbeton massiv | AF8: (beheizter Keller) | AG8: Dämmschichtdicke | AK8: 0 | AL8: [m] | AM8: Festgelegt WLG | AO8: 0.03
AG9: RT,Dämmung | AH9: = | AI9: Rsi | AJ9: + | AK9: ∑R (Dicke [m] | AL9: / | AM9: λ [W/mK]) | AN9: + | AO9: Rse
AG10: =AI10+(AK10/AM10)+AO10 -> 0 | AH10: = | AI10: =IF(AK8>0,'Kat. 1 U-Wert'!C48,0) -> 0 | AJ10: + | AK10: =AK8 -> 0 | AL10: / | AM10: =AO8 -> 0.03 | AN10: + | AO10: =IF(AK8>0,'Kat. 1 U-Wert'!C49,0) -> 0
AG11: RTDecke | AH11: = | AI11: 1 | AJ11: / | AK11: (gemäß Kat.1 U-Wert)
AG12: =AI12/AK12 -> 1 | AH12: = | AI12: 1 | AJ12: / | AK12: =AO6 -> 1
AG13: RT | AH13: = | AK13: (RTDecke | AL13: + | AM13: RT,Dämmung)
AG14: =AK14+AM14 -> 1 | AH14: = | AK14: =AG12 -> 1 | AL14: + | AM14: =AG10 -> 0
A16: Sanierungsempfehlung Gebäudehülle
O17: UGD saniert | U17: Dicke Dämmung NEU | X17: U-Wert NEU | Z17: U-Wert VORH | AC17: Lamda-Wert | AE17: Sanierungsempfehlung über Baujahr nach Gebiet oder Nutzereingabe
O18: HT [W/K] | U18: [m] | X18: [W/m²K] | Z18: [W/m²K] | AC18: λ [W/mK]) | AE18: Oberste Geschossdecke gedämmt | AF18: keine Empfehlung | AH18: Sanierungswunsch Ja / Nein Annahme Standardwärmedämmung EPS/XPS WLG (030) U-Wert gemäß BEG EM 0,25 [W/m²K]
O19: HT | P19: = | Q19: U | R19: * | S19: A | U19: =ROUNDUP(U23,2) -> 0.09 | X19: ='Kat. 1 U-Wert'!F99 -> 0.25 | Z19: =X7 -> 1 | AC19: =AO8 -> 0.03
O20: =Q20*S20 -> 17.5 | P20: = | Q20: =X19 -> 0.25 | R20: * | S20: =Z4 -> 70 | U20: einzubauende Dämmstärke | X20: gemäß BEG EM | Z20: Bestand | AC20: Dämmung Neu | AE20: Oberste Geschossdecke nicht gedämmt | AF20: Empfehlung Dämmung | AH20: aus Datenstufe 2 Bestandsaufnahme Annahme Standardwärmedämmung EPS/XPS WLG (032) U-Wert gemäß BEG EM 0,14 [W/m²K]
U22: dDä,NEU | W22: = | X22: (1/UNEU | Z22: - | AA22: 1/UVORH) | AC22: * | AD22: λDä,NEU | AE22: Dämmung >40 Jahre Bewertung als sanierungsbedürftig | AF22: Komplettsanierung | AH22: aus Datenstufe 2 Bestandsaufnahme Annahme Standardwärmedämmung EPS/XPS WLG (032) U-Wert gemäß BEG EM 0,14 [W/m²K]
U23: =(X23-AA23)*AD23 -> 0.09 | W23: = | X23: =1/X19 -> 4 | Z23: - | AA23: =1/X7 -> 1 | AC23: * | AD23: =AC19 -> 0.03
O25: Platzhalter für Kosten

Sheet Heizung
A4: Heizungssystem - Bestand
A5: Endenergie-Aufwandszahl e th,ges | B5: System | D5: zentral
D6: zentral mit Zusatzheizung
D7: dezentral
B9: Jahresverbrauch Wertermittlung (kWh) | D9: Nutzereingabe in kWh
B11: Wärmeerzeugung zentral | C11: Baujahr über LOD oder Alterseingabe (gemäß Kat.2 Heizung) | D11: Nutzereingabe der Heizungsanlage | F11: Sanierungsempfehlung
C12: Öl | D12: Standardkessel | F12: Sanierungsempfehlung
D13: Niedertemperaturkessel | F13: Sanierungsempfehlung
D14: Brennwertkessel | F14: Sanierungsempfehlung
C17: Erdgas | D17: Standardkessel | F17: Sanierungsempfehlung
D18: Niedertemperaturkessel | F18: Sanierungsempfehlung
D19: Brennwertkessel | F19: Sanierungsempfehlung
C21: Biomasse | D21: Pellets | F21: keine Sanierungsempfehlung
D22: Scheitholz | F22: keine Sanierungsempfehlung
C24: Strom | D24: Luft-Wasser Wärmepumpe | F24: keine Sanierungsempfehlung
D25: Wasser-Wasser Wärmepumpe | F25: keine Sanierungsempfehlung
D26: Sole-Wasser Wärmepumpe Sonden | F26: keine Sanierungsempfehlung
D27: Sole-Wasser Wärmepumpe Erdkollektor | F27: keine Sanierungsempfehlung
D28: Stromdirektheizung | F28: Sanierungsempfehlung
C29: Fernwärme
B31: Zusatzheizung | C31: Sonne | D31: Solarthermie WWB | F31: keine Sanierungsempfehlung
D32: Solarthermie WWB und Heizung | F32: keine Sanierungsempfehlung
C34: Biomasse | D34: Pellets | F34: keine Sanierungsempfehlung
D35: Scheitholz | F35: keine Sanierungsempfehlung
B37: Heizflächenart | C37: Heizkörper
C38: Flächenheizung (Fußboden-, Wand-, Deckenheizung)
C39: Einzelöfen
B40: Zusatzimfomation für Sanierungsempfehlung
C41: Photovoltaik-Anlage vorhanden
C42: Photovoltaik-Anlage möglich | D42: Solarkataster
C44: Fernwärmeanschluss möglich | D44: Gebietszuordnung
C46: Gasanschluss vorhanden | D46: Gebietszuordnung
C48: Umstellung auf Flächenheizung geplant
C50: Brennstofflagerfläche im Gebäude vorhanden
C51: Brennstofflagerfläche im Gebäude möglich

Sheet Berechnungen
B2: beheiztes Gebäudevolumen
B3: Ve | C3: = | D3: Grundfläche | E3: * | F3: Höhe | N3: Ve beheiztes Gebäudevolumen über LOD (Grundfläche x Höhe)
B4: [m³] | D4: [m²] | F4: [m]
B5: =D5*F5 -> 423.5 | C5: = | D5: 77 | E5: * | F5: 5.5
B7: beheiztes Luftvolumen
B8: VL | C8: = | D8: 0.76 | E8: * | F8: Ve | N8: VL beheiztes Luftvolumen [bis zu 3 Vollgeschosse (0,76 * Ve) oder übrige Fälle (0,80 * Ve) ]
B9: [m³] | D9: Fixwert | F9: [m³]
B10: =D10*F10 -> 321.86 | C10: = | D10: 0.76 | E10: * | F10: =B5 -> 423.5
B12: Nutzfläche über beheiztes Gebäudevolumen
B13: AN | C13: = | D13: 0.32 | E13: * | F13: Ve | N13: AN Nutzfläche nach GEG (0,32 * Ve )
B14: [m²] | D14: Fixwert | F14: [m³]
B15: =D15*F15 -> 135.52 | C15: = | D15: 0.32 | E15: * | F15: =F10 -> 423.5
B17: Nettogrundfläche EFH über Nutzfläche
B18: ANGF | C18: = | D18: 1,1/1,35 | E18: * | F18: AN | N18: ANGF EFH mit beheiztem Keller (1,1/1,35 * AN)
B19: [m²] | D19: Fixwert | F19: [m²] | N19: Abhängig vom Bestandsgebäude
B20: =D20*F20 -> 110.4237 | C20: = | D20: =1.1/1.35 -> 0.81481481 | E20: * | F20: =B15 -> 135.52
B22: Nettogrundfläche MFH über Nutzfläche
B23: ANGF | C23: = | D23: 1,1/1,2 | E23: * | F23: AN | N23: ANGF EFH ohne beheiztem Keller sowie MFH (1,1/1,2 * AN)
B24: [m²] | D24: Fixwert | F24: [m²] | N24: Abhängig vom Bestandsgebäude
B25: =D25*F25 -> 124.22667 | C25: = | D25: =1.1/1.2 -> 0.91666667 | E25: * | F25: =B15 -> 135.52
B27: Nettgrundfläche über Wohnfläche
B28: ANGF | C28: = | D28: 1.1 | E28: * | F28: AWohn | N28: ANGF (1,1 * Awohn)
B29: [m²] | D29: Fixwert | F29: [m²]
B30: =D30*F30 -> 128.33333 | C30: = | D30: =1.1/1.2 -> 0.91666667 | E30: * | F30: 140
B32: Gesamtluftwechsel ohne mech. Lüftung (Lüftungswärmeverlust)
B33: HV | C33: = | D33: n | E33: * | F33: 0.34 | G33: * | H33: VL | N33: HV Gesamtluftwechsel ohne mechanische Lüftung (Infiltration+Fenster)
B34: [W/K] | D34: [h-1] | F34: Fixwert | H34: [m³] | N34: 0,34 Produkt aus Dichte und spez. Wärmekapazität von Luft [Wh/m³K]
B35: =D35*F35*H35 -> 86.451596 | C35: = | D35: 0.79 | E35: * | F35: 0.34 | G35: * | H35: =B10 -> 321.86 | N35: n = ninf + nwin (Kategorie 3 Gebäudebestand n = 0,79)
B37: Gesamtwärmeverlust
B38: H | C38: = | D38: HV | E38: + | F38: HT | N38: HV = Lüftungswärmeverlust
B39: [W/K] | D39: [W/K] | F39: [W/K] | N39: HT = Tranmissionswärmeverlust aller Bauteile inkl Wärmebrücken
B40: =ROUNDUP(D40+F40,0) -> 594 | C40: = | D40: =B35 -> 86.451596 | E40: + | F40: =ROUNDUP(Grobkonzept!H72,0) -> 507
B42: Gesamt-Lüftungswärmesenken ohne mech. Lüftung
B43: QV | C43: = | D43: HV | E43: * | F43: Θi | G43: - | H43: Θe | I43: * | J43: 0.001 | K43: * | L43: t | N43: QV Gesamt-Lüftungswärmsenken | Q43: t = 24 Stunden pro Tag [h/d]
B44: [kWh/d] | D44: [W/K] | F44: [°C] | H44: [°C] | J44: Fixwert [kW] | L44: [h/d] | N44: Θi = Bilanz-Innentemperatur Gebäudezone [20°C] | R44: Θe = durchschnittliche monatliche Außentemperatur [°C]
B45: QV [kWh/a] | C45: = | D45: HV [W/K] | E45: * | F45: HDD [Kd/a] | I45: * | J45: 24/1000 [Fixwert] | M45: <-- | N45: angepasste Formel zur weiteren Berechnung
B46: =D46*F46*J46 -> 7523.3637 | C46: = | D46: =B35 -> 86.451596 | E46: * | F46: 3626 | I46: * | J46: 0.024
B48: Interne Wärmequellen über Nettogrundfläche
B49: Ql,source | C49: = | D49: ql | E49: * | F49: ANGF | G49: * | H49: 0.001 | N49: Interne Wärmequellen mit ql = 45Wh/m²d (EFH) oder 90 Wh/m²d (MFH)
B50: [kWh] | D50: [W/m²d] | F50: [m²] | H50: Fixwert [kW]
...

Sheet Kat. 1 U-Wert
A1: Quelle: Bundesanzeiger - Bekanntmachung der Regeln zur Datenaufnahme und Datenverwendung im Wohngebäudebestand vom 08. Oktober 2020
A2: Tabelle 2: Pauschalwerte für den Wärmedurchgangskoeffizienten
A3: Bauteil | B3: Konstruktion | C3: Baualtersklassen
C4: bis 1918 | D4: 1919 bis 1948 | E4: 1949 bis 1957 | F4: 1958 bis 1968 | G4: 1969 bis 1978 | H4: 1979 bis 1983 | I4: 1984 bis 1994 | J4: 1995 bis 2001 | K4: 2002 bis 2006
C5: Pauschalwerte für den Wärmedurchgangskoeffizienten in W/(m²*K)
A6: Dach | B6: Massive Konstruktion | C6: 2.1 | D6: 2.1 | E6: 2.1 | F6: 1.3 | G6: 1.3 | H6: 0.6 | I6: 0.4 | J6: 0.3 | K6: 0.2
B7: Holzkonstruktion | C7: 2.6 | D7: 1.4 | E7: 1.4 | F7: 1.4 | G7: 0.8 | H7: 0.7 | I7: 0.5 | J7: 0.3 | K7: 0.2
A9: Oberste Geschossdecke | B9: Massive Decke | C9: 2.1 | D9: 2.1 | E9: 2.1 | F9: 2.1 | G9: 0.6 | H9: 0.6 | I9: 0.3 | J9: 0.3 | K9: 0.2
B10: Holzbalkendecke | C10: 1 | D10: 1 | E10: 0.8 | F10: 0.7 | G10: 0.6 | H10: 0.4 | I10: 0.3 | J10: 0.3 | K10: 0.3
A12: Außenwand massive Konstruktion | B12: Zweischalige Wandaufbauten | C12: 1.3 | D12: 1.3 | E12: 1.3 | F12: 1.4 | G12: 1 | H12: 0.8 | I12: 0.6 | J12: 0.5 | K12: 0.4
B13: Zweischalige Wand- aufbauten mit Dämmung | C13: keine Angabe | D13: keine Angabe | E13: 1 | F13: 0.9 | G13: 0.9 | H13: 0.7 | I13: 0.5 | J13: 0.5 | K13: 0.4
B14: Massivwand aus Vollziegel bis 20cm Wandstärke | C14: 2.8 | D14: 2.8 | E14: 2.8 | F14: keine Angabe | G14: keine Angabe | H14: keine Angabe | I14: keine Angabe | J14: keine Angabe | K14: keine Angabe
B15: Wie vorstehend, jedoch 20 bis 30cm Wandstärke | C15: 1.8 | D15: 1.8 | E15: 1.8 | F15: keine Angabe | G15: keine Angabe | H15: keine Angabe | I15: keine Angabe | J15: keine Angabe | K15: keine Angabe
B16: Wie vorstehend, jedoch über 30cm Wandstärke | C16: 1.5 | D16: 1.5 | E16: 1.5 | F16: keine Angabe | G16: keine Angabe | H16: keine Angabe | I16: keine Angabe | J16: keine Angabe | K16: keine Angabe
B17: Massivwand aus Hochlochziegel | C17: 1.4 | D17: 1.4 | E17: 1.4 | F17: 1.4 | G17: 1 | H17: 0.8 | I17: 0.6 | J17: 0.5 | K17: 0.4
B18: Sonstige massive Wandaufbauten bis 20cm Wandstärke | C18: 3 | D18: 3 | E18: 3 | F18: 1.4 | G18: 1 | H18: 0.8 | I18: 0.7 | J18: 0.7 | K18: 0.4
B19: Sonstige Wandaufbauten über 20cm Wandstärke | C19: 2.2 | D19: 2.2 | E19: 2.2 | F19: 1.4 | G19: 1 | H19: 0.8 | I19: 0.6 | J19: 0.5 | K19: 0.4
A21: Außenwand Holzkonstruktion (Fachwerk, Fertighaus) | B21: Massivholzwand, Holzrahmen oder Holztafelwand | C21: 0.5 | D21: 0.5 | E21: 0.5 | F21: 0.5 | G21: 0.5 | H21: 0.5 | I21: 0.4 | J21: 0.4 | K21: 0.3
B22: Sonstige Holzkonstruktion | C22: 2 | D22: 2 | E22: 1.5 | F22: 1.4 | G22: 0.6 | H22: 0.5 | I22: 0.4 | J22: 0.4 | K22: 0.3
A24: Sonstige Bauteile gg. Erdreich oder unbeheizte Räume | B24: Kellerdecke Stahlbeton massiv | C24: 1.6 | D24: 1.6 | E24: 2.3 | F24: 1 | G24: 1 | H24: 0.8 | I24: 0.6 | J24: 0.6 | K24: 0.5
B25: Kellerdecke als Holzbalkendecke | C25: 1 | D25: 1 | E25: 1 | F25: 0.8 | G25: 0.6 | H25: 0.6 | I25: 0.4 | J25: 0.4 | K25: 0.4
B26: Boden gegen Erdreich, Stahlbeton massiv | C26: 1.6 | D26: 1.6 | E26: 2.3 | F26: 1.2 | G26: 1.2 | H26: 0.8 | I26: 0.6 | J26: 0.6 | K26: 0.5
A28: Türen | B28: Im Wesentlichen aus Metall | C28: 4
B29: Im Wesentlichen aus Holz, Holzwerkstoffen oder Kunststoff | C29: 2.9
A31: Bauteil | B31: Konstruktion | F31: Eigen- schaft | G31: Baualtersklasse
G32: bis 1978 | H32: 1979 bis 1983 | I32: 1984 bis 1994 | J32: 1995 bis 2001 | K32: ab 2002
A35: Fenster, Fenstertüren | B35: Holzfenster, einfach verglast | F35: UW | G35: 5 | H35: keine Angabe | I35: keine Angabe | J35: keine Angabe | K35: keine Angabe
F36: Glas | G36: einfach | H36: keine Angabe | I36: keine Angabe | J36: keine Angabe | K36: keine Angabe
B37: Holzfenster, zwei Scheiben | F37: UW | G37: 2.7 | H37: 2.7 | I37: 2.7 | J37: 1.6 | K37: 1.5
F38: Glas | G38: zweifach | H38: zweifach | I38: zweifach | J38: MSIV 2 | K38: MSIV 2
B39: Kunststofffenster, Isolierverglasung | F39: UW | G39: 3 | H39: 3 | I39: 3 | J39: 1.9 | K39: 1.5
F40: Glas | G40: zweifach | H40: zweifach | I40: zweifach | J40: MSIV 2 | K40: MSIV 2
B41: Aluminium- oder Stahlfenster, Isolierverglasung | F41: UW | G41: 4.3 | H41: 4.3 | I41: 3.2 | J41: 1.9 | K41: 1.5
F42: Glas | G42: zweifach | H42: zweifach | I42: zweifach | J42: MSIV 2 | K42: MSIV 2
A43: MSIV 2 = Mehrscheibenisolierverglasung
A46: Tabelle: Wärmeübergangswiderstände (R-Werte Rsi und Rse) für an Außenluft grenzende Räume
A47: Wärmeübergangswiderstand | C47: aufwärts | E47: horizontal | G47: abwärts
A48: Rsi | C48: 0.1 | E48: 0.13 | G48: 0.17
A49: Rse | C49: 0.04 | E49: 0.04 | G49: 0.04
A52: Quelle: Bundesanzeiger - Richtlinie für die Bundesförderung für effiziente Gebäude - Einzelmaßnahmen (BEG EM) vom 21. Dezember 2023
...

Sheet Kat. 2 Heizung
A2: Endenergie-Aufwandszahl | B2: Durchschnittswerte für die Raumheizung und Warmwasserbereitung (ohne Hilfsenergie)
C3: Baualter | D3: Aufwandszahl e
B4: Standardkessel (auch Holzkessel) | C4: bis 1986 | D4: 1.6
C5: 1987 - 1994 | D5: 1.5
C6: ab 1995 | D6: 1.4
B7: Niedertemperaturkessel Öl / Gas | C7: bis 1986 | D7: 1.4
C8: ab 1987 | D8: 1.3
B9: Gas-Brennwert | C9: - | D9: 1.2
B10: Elektrowärmepumpe Erdreich | C10: bis 1994 | D10: 0.4
C11: ab 1995 | D11: 0.3
B12: Elektrowärmepumpe Luft | C12: bis 1994 | D12: 0.5
C13: ab 1995 | D13: 0.4
A16: Tabelle 22 - Aufwandszahl für bauteilintegrierten Heizflächen (Flächenheizungen); lichte Raumhöhe ≤ 4m | F16: Aufwandszahl für freie Heizflächen - Raumhöhe ≤ 4m
A17: Einflussparameter | D17: eh,ce,0 | F17: Einflussparameter | I17: eh,ce,0
A18: Raumtemperaturregelung | B18: ungeregelt, mit zentraler Zulauftemperaturregelung | D18: 1.149 | F18: Raumtemperaturregelung | G18: ungeregelt, mit zentraler Zulauftemperaturregelung | I18: 1.149
B19: Führungsraumregelung- oder Ein-Rohr-Heizung | D19: 1.107 | G19: Führungsraumregelung- oder Ein-Rohr-Heizung | I19: 1.107
B20: Raumtemperaturregelung (elektromechanisch/elektronisch) | D20: 1.095 | G20: Raumtemperaturregelung (elektromechanisch/elektronisch) | I20: 1.095
B21: P-Regler (vor 1988) | D21: 1.083 | G21: P-Regler (vor 1988) | I21: 1.083
B22: P-Regler, 2-Punkt-Regler (Hysterese ≤ 0,5K | D22: 1.042 | G22: P-Reglera | I22: 1.042
B23: PI-Reglera | D23: 1.042 | G23: PI-Reglera | I23: 1.042
B24: PID-Regler (mit Optimierungsfunktion, z.B. Anwesenheits- management, adaptivem Regler)a | D24: 1.03 | G24: PID-Regler (mit Optimierungsfunktion, z.B. Anwesenheits- management, adaptivem Regler)a | I24: 1.03
A26: Zu- / Abschlag auf Aufwandszahl eh,ce,0 | F26: Zu- / Abschlag auf Aufwandszahl eh,ce,0
D27: ∆eh,ce,1 | I27: ∆eh,ce,1
A28: System | B28: Fußbodenheizung | F28: Übertemperatur | G28: Zwei-Rohr-Heizung und Ein-Rohr-Heizung, erneuert
B29:  Nasssystem | D29: 0.021 | G29: 60K (z.B. 90°C / 70°C) | I29: 0.036
B30:  Trockensystem | D30: 0.012 | G30: 42,5K (z.B. 70°C / 55°C) | I30: 0.021
B31:  System mit niedriger Bedeckung | D31: 0.006 | G31: 30K (z.B. 55°C / 45°C) | I31: 0.015
B32: Wandheizung | D32: 0.045 | G32: 20K (z.B. 45°C / 35°C) | I32: 0.012
B33: Deckenheizung | D33: 0.063 | G33: Ein-Rohr-Heizung (nicht erneuert)
B34: Heizungsanlage in Verbindung mit mechanischer Lüftung | D34: 0 | G34: 60K (z.B. 90°C / 70°C) | I34: 0.048
D35: ∆eh,ce,2 | G35: 42,5K (z.B. 70°C / 55°C) | I35: 0.036
A36: spezifische Wärmeverlust übe angrenzende Flächen | B36: integrierte Heizfläche ohne Mindestdämmung nach DIN EN 1264 (alle Teile) | D36: 0.042 | G36: Heizungsanlage in Verbindung mit mechanischer Lüftung | I36: 0.006
G37: Radiatoren mit Gebläse | I37: 0
B38: integrierte Heizfläche mit Mindestdämmung nach DIN EN 1264 (alle Teile) | D38: 0.015 | I38: ∆eh,ce,2
F39: spezifische Wärmeverlust über Außenbauteile (GF = Glasfläche) | G39: Radiatorenposition Innenwand | I39: 0.039
B40: integrierte Heizfläche einer 100% besseren Dämmung als nach DIN EN 1264 (alle Teile) gefordert | D40: 0.003 | G40: Radiatorenposition Außenwand
G41:  Glasfläche ohne Strahlungsschutz | I41: 0.051
G42:  Glasfläche mit Strahlungsschutz | I42: 0.036
G43:  Außenwand | I43: 0.009
I44: ∆eh,ce,3
...

Sheet Formeln
A3: Jahres-Heizwärmebedarf kWh/a | D3: [Gradtagsfaktor x (Transmissionswärmeverlust + Lüftungswärmeverlust)] - [Nutzungsgrad interner Gewinne x (solare Gewinne + interne Gewinne)]
A5: Interne Wärmegewinne W/m² | D5: 5 x Nutzfläche x Länge der Heizperiode x 0,024 (Länge der Heizperiode im Durchschnitt 185 Tage)
A7: Solare Gewinne | D7: ∑ (Einstrahlung x Energiedurchlassgrad der Fenster x Fläche X Korrekturfaktoren) pro Himmelsrichtung
A9: Wärmebedarf | D9: Transmissionswärmeverlust + Lüftungswärmeverlust
A11: Transmissionswärmeverlust HT | D11: ∑ (Korrekturfaktor x U-Wert x Bauteilfläche) + (Wärmebrückenzuschlag x Hüllfläche des Gebäudes) | S11: Absoluter Wert
A13: spezifischer Transmissionswärmeverlust HT' | D13: Transmissionswärmeverlust HT / thermische Hüllfläche | S13: Flächenbezogen
A15: Nutzfläche ANG | D15: Gebäudevolumen x 0,32
A17: Gradtagszahl Kd/a | D17: Außentemperatur unter einer festgelegten Heizgrenztemperatur (regional) (Bsp.: dena-Energiepass)
A19: Gradtagsfaktor kKh | D19: Gradtagszahl x Faktor 0,024
A21: Lüftungswärmetransferkoeffizient HV [W/K] | D21: 0,34 x Luftwechselrate x beheiztes Luftvolumen (Luftwechselrate aus DIN 18599 Tabelle 12 - 14)
A26: Kleinbuchstaben beziehen sich auf m² / Großbuchstaben beziehen sich auf den Jahreswert
