Workbook

Sheet Dach-Fenster
A1: DACH & DACHFENSTER
A3: ERGEBNIS-ZUSAMMENFASSUNG
B4: Bauteil | D4: Fläche A [m²] | F4: U-Wert [W/m²K] | H4: Korrekturfaktor F | J4: HT [W/K] | L4: ∆UWB [W/m²K] | N4: Ages [m²]
B5: Dach | D5: =D14 -> 90.5 | F5: =D16 -> 0.2535 | H5: =D17 -> 1 | J5: =I34 -> 22.94175
B6: Dachfenster | D6: =D21 -> 9.5 | F6: =D22 -> 2 | H6: =D23 -> 0.93 | J6: =I35 -> 17.67 | L6: =I38 -> 0.1 | N6: =I39 -> 100
A8: BESTANDSAUFNAHME DACH
B9: Parameter | D9: Wert | E9: Einheit | G9: Datenstufe 1 | I9: Datenstufe 2
B10: Dachraum beheizt | G10: Ja / Nein | I10: Ja / Nein
B11: Dachform | G11: Flachdach / Satteldach | I11: Flachdach / Satteldach
B12: Konstruktion | G12: ='Kat. 1 U-Wert'!B6 -> Massive Konstruktion | I12: ='Kat. 1 U-Wert'!B7 -> Holzkonstruktion
B13: Gesamtdachfläche | D13: 100 | E13: m² | G13: LOD oder Nutzereingabe | I13: Nutzereingabe der Fläche
B14: Dachfläche (netto) | D14: =D13-D21 -> 90.5 | E14: m² | G14: Dachfläche − Dachfensterfläche
B15: U-Wert Bestand (ohne Korr.) | D15: =I31 -> 0.195 | E15: W/m²K | G15: Baujahr über LOD (gemäß Kat.1) | I15: Berechnung über Bauteilschichten
B16: U-Wert Bestand (mit Korr.) | D16: =D15*D18 -> 0.2535 | E16: W/m²K | G16: U-Wert × Minderungsfaktor
B17: Korrekturfaktor F | D17: 1
B18: Minderungsfaktor | D18: 1.3 | G18: kein Korrekturfaktor bei Aufsparren
A20: BESTANDSAUFNAHME DACHFENSTER
B21: Fläche Dachfenster | D21: 9.5 | E21: m² | G21: LOD | I21: Nutzereingabe der Fläche
B22: U-Wert Dachfenster | D22: 2 | E22: W/m²K | G22: Baujahr über LOD (gemäß Kat.1) | I22: Angabe des U-Werts über Nutzereingabe
B23: Korrekturfaktor F | D23: 0.93
B24: Konstruktionsart | G24: ='Kat. 1 U-Wert'!B37 -> Holzfenster, zwei Scheiben | I24: oder Alterseingabe gemäß Kat.1 U-Wert über
G25: ='Kat. 1 U-Wert'!B39 -> Kunststofffenster, Isolierverglasung | I25: Rahmenart und Glasart
A27: BERECHNUNG
B28: Berechnung | D28: Formel | I28: Ergebnis | J28: Einheit
B29: R-Wert Zwischensparren | D29: Rsi + Σ(d/λ) + Rse | I29: ='Kat. 1 U-Wert'!C48+(0.2/0.04)+'Kat. 1 U-Wert'!C49 -> 5.14 | J29: m²K/W
B30: R-Wert Aufsparren | D30: Rsi + Σ(d/λ) + Rse | I30: ='Kat. 1 U-Wert'!C48+(0.2/0.04+0.25/2.3)+'Kat. 1 U-Wert'!C49 -> 5.2486957 | J30: m²K/W
B31: U-Wert (aus Zwischensparren) | D31: U = (1 / RT) | I31: =ROUND(1/I29,3) -> 0.195 | J31: W/m²K
B32: U-Wert (aus Aufsparren) | D32: U = (1 / RT) | I32: =ROUND(1/I30,3) -> 0.191 | J32: W/m²K
B34: HT Dach | D34: HT = F × U × A | I34: =D17*D16*D14 -> 22.94175 | J34: W/K
B35: HT Dachfenster | D35: HT = F × U × A | I35: =D23*D22*D21 -> 17.67 | J35: W/K
B36: ∑ HT Gesamt | D36: HT,Dach + HT,Fenster | I36: =I34+I35 -> 40.61175 | J36: W/K
B38: Wärmebrückenzuschlag ∆UWB | D38: pauschal | I38: 0.1 | J38: W/m²K
B39: Ages (Hüllfläche) | D39: Dachfläche + Fensterfläche | I39: =D14+D21 -> 100 | J39: m²
B40: HT (mit Wärmebrücken) | D40: ∑HT + ∆UWB × Ages | I40: =I36+(I38*I39) -> 50.61175 | J40: W/K
B41: HT' (flächenbezogen) | D41: HT / Ages | I41: =I40/I39 -> 0.5061175 | J41: W/m²K
A43: SANIERUNGSEMPFEHLUNG
B44: Bauteil / Bewertung | D44: Empfehlung | F44: U-Wert Ziel [W/m²K] | H44: Maßnahme / Annahmen
B45: Dach saniert (beheizt) | H45: Sanierungsempfehlung über geschätztes Baujahr
B46: < 20 Jahre (neues Dach) | D46: keine Empfehlung | F46: Bestand | H46: Sanierungswunsch Ja / Nein
B47: 20–40 Jahre (sanierungsbedürftig) | D47: Empfehlung Dämmung | F47: 0,14 | H47: Mineralwolle WLG (035), U-Wert gemäß BEG EM
...

Sheet OGD
A1: OBERSTE GESCHOSSDECKE (OGD)
A3: ERGEBNIS-ZUSAMMENFASSUNG
B4: Bauteil | D4: Fläche A [m²] | F4: U-Wert [W/m²K] | H4: Korrekturfaktor F | I4: HT [W/K]
B5: OGD | D5: =D10 -> 0 | F5: =D11 -> 0 | H5: =D13 -> 0 | I5: =I20 -> 0
A8: BESTANDSAUFNAHME OGD
B9: Parameter | D9: Wert | E9: Einheit | G9: Datenstufe 1 | I9: Datenstufe 2
B10: Dachraum beheizt | G10: Ja / Nein | I10: Ja / Nein
B11: Fläche OGD | E11: m² | G11: LOD Grundfläche oder Nutzereingabe | I11: Nutzereingabe der Fläche
B12: U-Wert Bestand | E12: W/m²K | G12: Baujahr über LOD (gemäß Kat.1) | I12: Berechnung über Bauteilschichten
B13: Konstruktion | G13: ='Kat. 1 U-Wert'!B9 -> Massive Decke | I13: ='Kat. 1 U-Wert'!B9 -> Massive Decke
G14: ='Kat. 1 U-Wert'!B10 -> Holzbalkendecke | I14: ='Kat. 1 U-Wert'!B10 -> Holzbalkendecke
B15: Korrekturfaktor F | I15: Dämmschichtdicke / WLG
A17: BERECHNUNG
B18: Berechnung | D18: Formel | I18: Ergebnis | J18: Einheit
B19: HT OGD | D19: HT = F × U × A | I19: =D13*D11*D10 -> 0 | J19: W/K
B20: ∑ HT OGD Gesamt | D20: HT,OGD | I20: =I19 -> 0 | J20: W/K
A22: SANIERUNGSEMPFEHLUNG
B23: Bauteil / Bewertung | D23: Empfehlung | F23: U-Wert Ziel [W/m²K] | H23: Maßnahme / Annahmen
B24: OGD saniert | H24: Sanierungsempfehlung über Baujahr
B25: OGD gedämmt | D25: keine Empfehlung | F25: Bestand | H25: Sanierungswunsch Ja / Nein
B26: OGD nicht gedämmt | D26: Empfehlung Dämmung | F26: 0,14 | H26: EPS/XPS WLG (032), U-Wert gemäß BEG EM
B27: Dämmung >40 Jahre (sanierungsbedürftig) | D27: Komplettsanierung | F27: 0,14 | H27: EPS/XPS WLG (032), U-Wert gemäß BEG EM
B29: Platzhalter für Kosten

Sheet AW-Fenster
A1: AUSSENWAND & FENSTER
A3: ERGEBNIS-ZUSAMMENFASSUNG
B4: Bauteil | D4: Fläche A [m²] | F4: U-Wert [W/m²K] | H4: Korrekturfaktor F | I4: HT [W/K]
B5: Außenwand | D5: =D10 -> 0 | F5: =D11 -> 0 | H5: =D12 -> 0 | I5: =I28 -> 0
B6: Fenster / Türen | D6: =D17 -> 0 | F6: =D18 -> 0 | H6: =D19 -> 0 | I6: =I29 -> 0
A8: BESTANDSAUFNAHME AUSSENWAND
B9: Parameter | D9: Wert | E9: Einheit | G9: Datenstufe 1 | I9: Datenstufe 2
B10: Fläche Außenwand | E10: m² | G10: LOD (Umfang × Höhe − 30% Fenster) | I10: Nutzereingabe der Fläche
B11: U-Wert Bestand | E11: W/m²K | G11: Baujahr über LOD (gemäß Kat.1) | I11: Berechnung über Bauteilschichten
B12: Korrekturfaktor F
B13: Konstruktion | G13: ='Kat. 1 U-Wert'!B19 -> Sonstige Wandaufbauten über 20cm Wandstärke | I13: AW-Konstruktion (gemäß Kat.1)
G14: ='Kat. 1 U-Wert'!B16 -> Wie vorstehend, jedoch über 30cm Wandstärke | I14: Dämmschichtdicke / WLG
A16: BESTANDSAUFNAHME FENSTER / TÜREN
B17: Fläche Fenster / Türen | E17: m² | G17: LOD (30% der Gesamtaußenwandfläche) | I17: Nutzereingabe der Fläche
B18: U-Wert Fenster | E18: W/m²K | G18: Baujahr über LOD (gemäß Kat.1) | I18: Berechnung über Bauteilschichten
B19: Korrekturfaktor F
B20: Konstruktionsart | G20: ='Kat. 1 U-Wert'!B37 -> Holzfenster, zwei Scheiben | I20: Alterseingabe gemäß Kat.1 U-Wert über
G21: ='Kat. 1 U-Wert'!B39 -> Kunststofffenster, Isolierverglasung | I21: Rahmenart und Glasart
A24: BERECHNUNG
B25: Berechnung | D25: Formel | I25: Ergebnis | J25: Einheit
B27: HT Außenwand | D27: HT = F × U × A | I27: =D12*D11*D10 -> 0 | J27: W/K
B28: HT Fenster / Türen | D28: HT = F × U × A | I28: =D19*D18*D17 -> 0 | J28: W/K
B29: ∑ HT Gesamt | D29: HT,AW + HT,Fenster | I29: =I27+I28 -> 0 | J29: W/K
A31: SANIERUNGSEMPFEHLUNG
B32: Bauteil / Bewertung | D32: Empfehlung | F32: U-Wert Ziel [W/m²K] | H32: Maßnahme / Annahmen
B33: Außenwand saniert | H33: Sanierungsempfehlung über Baujahr
B34: AW gedämmt | D34: keine Empfehlung | F34: Bestand | H34: Sanierungswunsch Ja / Nein
B35: AW nicht gedämmt | D35: Empfehlung Dämmung | F35: 0,20 | H35: EPS WLG (035), U-Wert gemäß BEG EM
B36: Dämmung >50 Jahre (sanierungsbedürftig) | D36: Empfehlung Dämmungaustausch | F36: 0,20 | H36: EPS WLG (035), U-Wert gemäß BEG EM
B38: Fenster saniert | H38: Fenstertausch über Baujahr
B39: < 30 Jahre (neueres Fenster) | D39: keine Empfehlung | F39: Bestand | H39: Sanierungswunsch Ja / Nein
B40: > 30 Jahre (sanierungsbedürftig) | D40: Fenstertausch | F40: 0,95 | H40: Kunststoff-/Holzrahmen, U-Wert gemäß BEG EM
B42: Platzhalter für Kosten

Sheet UGD
A1: UNTERSTE GESCHOSSDECKE (UGD)
A3: ERGEBNIS-ZUSAMMENFASSUNG
B4: Bauteil | D4: Fläche A [m²] | F4: U-Wert [W/m²K] | H4: Korrekturfaktor F | I4: HT [W/K]
B5: UGD | D5: =D10 -> 0 | F5: =D11 -> 0 | H5: =D13 -> 0 | I5: =I19 -> 0
A8: BESTANDSAUFNAHME UGD
B9: Parameter | D9: Wert | E9: Einheit | G9: Datenstufe 1 | I9: Datenstufe 2
B10: Fläche UGD | E10: m² | G10: LOD Grundfläche oder Nutzereingabe | I10: Nutzereingabe der Fläche
B11: U-Wert Bestand | E11: W/m²K | G11: Baujahr über LOD (gemäß Kat.1) | I11: Berechnung über Bauteilschichten
B12: Konstruktion | G12: ='Kat. 1 U-Wert'!B24 -> Kellerdecke Stahlbeton massiv | I12: ='Kat. 1 U-Wert'!B24 -> Kellerdecke Stahlbeton massiv
G13: ='Kat. 1 U-Wert'!B25 -> Kellerdecke als Holzbalkendecke | I13: ='Kat. 1 U-Wert'!B25 -> Kellerdecke als Holzbalkendecke
G14: ='Kat. 1 U-Wert'!B26 -> Boden gegen Erdreich, Stahlbeton massiv | I14: Dämmschichtdicke / WLG
B15: Korrekturfaktor F
A17: BERECHNUNG
B18: Berechnung | D18: Formel | I18: Ergebnis | J18: Einheit
B19: HT UGD | D19: HT = F × U × A | I19: =D15*D11*D10 -> 0 | J19: W/K
B20: ∑ HT UGD Gesamt | D20: HT,UGD | I20: =I19 -> 0 | J20: W/K
A22: SANIERUNGSEMPFEHLUNG
B23: Bauteil / Bewertung | D23: Empfehlung | F23: U-Wert Ziel [W/m²K] | H23: Maßnahme / Annahmen
B24: UGD saniert | H24: Sanierungsempfehlung über Baujahr
B25: UGD gedämmt | D25: keine Empfehlung | F25: Bestand | H25: Sanierungswunsch Ja / Nein
B26: UGD nicht gedämmt | D26: Empfehlung Dämmung | F26: 0,25 | H26: EPS/XPS WLG (030), U-Wert gemäß BEG EM
B28: Platzhalter für Kosten

Sheet Heizung
A1: HEIZUNGSSYSTEM – BESTAND
A3: SYSTEM & VERBRAUCH
B4: Systemart | D4: zentral / zentral mit Zusatz / dezentral
B5: Jahresverbrauch (kWh) | D5: Eingabe kWh
B6: Baujahr Heizung | D6: Eingabe
A8: WÄRMEERZEUGUNG ZENTRAL
B9: Energieträger | D9: Erzeugerart | F9: Sanierungsempfehlung
B10: Öl | D10: Standardkessel | F10: Sanierungsempfehlung
D11: Niedertemperaturkessel | F11: Sanierungsempfehlung
D12: Brennwertkessel | F12: Sanierungsempfehlung
B14: Erdgas | D14: Standardkessel | F14: Sanierungsempfehlung
D15: Niedertemperaturkessel | F15: Sanierungsempfehlung
D16: Brennwertkessel | F16: Sanierungsempfehlung
B18: Biomasse | D18: Pellets | F18: keine Sanierungsempfehlung
D19: Scheitholz | F19: keine Sanierungsempfehlung
B21: Strom | D21: Luft-Wasser Wärmepumpe | F21: keine Sanierungsempfehlung
D22: Wasser-Wasser Wärmepumpe | F22: keine Sanierungsempfehlung
D23: Sole-Wasser WP Sonden | F23: keine Sanierungsempfehlung
D24: Sole-Wasser WP Erdkollektor | F24: keine Sanierungsempfehlung
D25: Stromdirektheizung | F25: Sanierungsempfehlung
B27: Fernwärme
A29: ZUSATZHEIZUNG
B30: Sonne | D30: Solarthermie WWB | F30: keine Sanierungsempfehlung
D31: Solarthermie WWB und Heizung | F31: keine Sanierungsempfehlung
B33: Biomasse | D33: Pellets | F33: keine Sanierungsempfehlung
D34: Scheitholz | F34: keine Sanierungsempfehlung
A36: HEIZFLÄCHENART
B37: Heizkörper
B38: Flächenheizung (Fußboden-, Wand-, Deckenheizung)
B39: Einzelöfen
A41: ZUSATZINFORMATIONEN FÜR SANIERUNGSEMPFEHLUNG
B42: Photovoltaik-Anlage vorhanden
B43: Photovoltaik-Anlage möglich | D43: Solarkataster
B45: Fernwärmeanschluss möglich | D45: Gebietszuordnung
B47: Gasanschluss vorhanden | D47: Gebietszuordnung
B49: Umstellung auf Flächenheizung geplant
B51: Brennstofflagerfläche im Gebäude vorhanden/möglich

Sheet Kat. 1 U-Wert
A1: Quelle: Bundesanzeiger - Bekanntmachung der Regeln zur Datenaufnahme und Datenverwendung im Wohngebäudebestand vom 08. Oktober 2020
A2: Tabelle 2: Pauschalwerte für den Wärmedurchgangskoeffizienten
A3: Bauteil | B3: Konstruktion | C3: Baualtersklassen
C4: bis 1918 | D4: 1919 bis 1948 | E4: 1949 bis 1957 | F4: 1958 bis 1968 | G4: 1969 bis 1978 | H4: 1979 bis 1983 | I4: 1984 bis 1994 | J4: 1995 bis 2001 | K4: 2002 bis 2006
C5: Pauschalwerte für den Wärmedurchgangskoeffizienten in W/(m²*K)
A6: Dach | B6: Massive Konstruktion | C6: 2.1 | D6: 2.1 | E6: 2.1 | F6: 1.3 | G6: 1.3 | H6: 0.6 | I6: 0.4 | J6: 0.3 | K6: 0.2
B7: Holzkonstruktion | C7: 2.6 | D7: 1.4 | E7: 1.4 | F7: 1.4 | G7: 0.8 | H7: 0.7 | I7: 0.5 | J7: 0.3 | K7: 0.2
A9: Oberste Geschossdecke | B9: Massive Decke | C9: 2.1 | D9: 2.1 | E9: 2.1 | F9: 2.1 | G9: 0.6 | H9: 0.6 | I9: 0.3 | J9: 0.3 | K9: 0.2
B10: Holzbalkendecke | C10: 1 | D10: 1 | E10: 0.8 | F10: 0.7 | G10: 0.6 | H10: 0.4 | I10: 0.3 | J10: 0.3 | K10: 0.3
A12: Außenwand massive Konstruktion | B12: Zweischalige Wandaufbauten | C12: 1.3 | D12: 1.3 | E12: 1.3 | F12: 1.4 | G12: 1 | H12: 0.8 | I12: 0.6 | J12: 0.5 | K12: 0.4
B13: Zweischalige Wand- aufbauten mit Dämmung | C13: keine Angabe | D13: keine Angabe | E13: 1 | F13: 0.9 | G13: 0.9 | H13: 0.7 | I13: 0.5 | J13: 0.5 | K13: 0.4
B14: Massivwand aus Vollziegel bis 20cm Wandstärke | C14: 2.8 | D14: 2.8 | E14: 2.8 | F14: keine Angabe | G14: keine Angabe | H14: keine Angabe | I14: keine Angabe | J14: keine Angabe | K14: keine Angabe
B15: Wie vorstehend, jedoch 20 bis 30cm Wandstärke | C15: 1.8 | D15: 1.8 | E15: 1.8 | F15: keine Angabe | G15: keine Angabe | H15: keine Angabe | I15: keine Angabe | J15: keine Angabe | K15: keine Angabe
B16: Wie vorstehend, jedoch über 30cm Wandstärke | C16: 1.5 | D16: 1.5 | E16: 1.5 | F16: keine Angabe | G16: keine Angabe | H16: keine Angabe | I16: keine Angabe | J16: keine Angabe | K16: keine Angabe
B17: Massivwand aus Hochlochziegel | C17: 1.4 | D17: 1.4 | E17: 1.4 | F17: 1.4 | G17: 1 | H17: 0.8 | I17: 0.6 | J17: 0.5 | K17: 0.4
B18: Sonstige massive Wandaufbauten bis 20cm Wandstärke | C18: 3 | D18: 3 | E18: 3 | F18: 1.4 | G18: 1 | H18: 0.8 | I18: 0.7 | J18: 0.7 | K18: 0.4
B19: Sonstige Wandaufbauten über 20cm Wandstärke | C19: 2.2 | D19: 2.2 | E19: 2.2 | F19: 1.4 | G19: 1 | H19: 0.8 | I19: 0.6 | J19: 0.5 | K19: 0.4
A21: Außenwand Holzkonstruktion (Fachwerk, Fertighaus) | B21: Massivholzwand, Holzrahmen oder Holztafelwand | C21: 0.5 | D21: 0.5 | E21: 0.5 | F21: 0.5 | G21: 0.5 | H21: 0.5 | I21: 0.4 | J21: 0.4 | K21: 0.3
B22: Sonstige Holzkonstruktion | C22: 2 | D22: 2 | E22: 1.5 | F22: 1.4 | G22: 0.6 | H22: 0.5 | I22: 0.4 | J22: 0.4 | K22: 0.3
A24: Sonstige Bauteile gg. Erdreich oder unbeheizte Räume | B24: Kellerdecke Stahlbeton massiv | C24: 1.6 | D24: 1.6 | E24: 2.3 | F24: 1 | G24: 1 | H24: 0.8 | I24: 0.6 | J24: 0.6 | K24: 0.5
B25: Kellerdecke als Holzbalkendecke | C25: 1 | D25: 1 | E25: 1 | F25: 0.8 | G25: 0.6 | H25: 0.6 | I25: 0.4 | J25: 0.4 | K25: 0.4
B26: Boden gegen Erdreich, Stahlbeton massiv | C26: 1.6 | D26: 1.6 | E26: 2.3 | F26: 1.2 | G26: 1.2 | H26: 0.8 | I26: 0.6 | J26: 0.6 | K26: 0.5
A28: Türen | B28: Im Wesentlichen aus Metall | C28: 4
B29: Im Wesentlichen aus Holz, Holzwerkstoffen oder Kunststoff | C29: 2.9
A31: Bauteil | B31: Konstruktion | F31: Eigen- schaft | G31: Baualtersklasse
G32: bis 1978 | H32: 1979 bis 1983 | I32: 1984 bis 1994 | J32: 1995 bis 2001 | K32: ab 2002
A35: Fenster, Fenstertüren | B35: Holzfenster, einfach verglast | F35: UW | G35: 5 | H35: keine Angabe | I35: keine Angabe | J35: keine Angabe | K35: keine Angabe
F36: Glas | G36: einfach | H36: keine Angabe | I36: keine Angabe | J36: keine Angabe | K36: keine Angabe
B37: Holzfenster, zwei Scheiben | F37: UW | G37: 2.7 | H37: 2.7 | I37: 2.7 | J37: 1.6 | K37: 1.5
F38: Glas | G38: zweifach | H38: zweifach | I38: zweifach | J38: MSIV 2 | K38: MSIV 2
B39: Kunststofffenster, Isolierverglasung | F39: UW | G39: 3 | H39: 3 | I39: 3 | J39: 1.9 | K39: 1.5
F40: Glas | G40: zweifach | H40: zweifach | I40: zweifach | J40: MSIV 2 | K40: MSIV 2
B41: Aluminium- oder Stahlfenster, Isolierverglasung | F41: UW | G41: 4.3 | H41: 4.3 | I41: 3.2 | J41: 1.9 | K41: 1.5
F42: Glas | G42: zweifach | H42: zweifach | I42: zweifach | J42: MSIV 2 | K42: MSIV 2
A43: MSIV 2 = Mehrscheibenisolierverglasung
A46: Tabelle: Wärmeübergangswiderstände (R-Werte Rsi und Rse) für an Außenluft grenzende Räume
A47: Wärmeübergangswiderstand | C47: aufwärts | E47: horizontal | G47: abwärts
A48: Rsi | C48: 0.1 | E48: 0.13 | G48: 0.17
A49: Rse | C49: 0.04 | E49: 0.04 | G49: 0.04

Sheet Kat. Heizung
A2: Endenergie-Aufwandszahl | B2: Durchschnittswerte für die Raumheizung und Warmwasserbereitung (ohne Hilfsenergie)
C3: Baualter | D3: Aufwandszahl e
B4: Standardkessel (auch Holzkessel) | C4: bis 1986 | D4: 1.6
C5: 1987 - 1994 | D5: 1.5
C6: ab 1995 | D6: 1.4
B7: Niedertemperaturkessel Öl / Gas | C7: bis 1986 | D7: 1.4
C8: ab 1987 | D8: 1.3
B9: Gas-Brennwert | C9: - | D9: 1.2
B10: Elektrowärmepumpe Erdreich | C10: bis 1994 | D10: 0.4
C11: ab 1995 | D11: 0.3
B12: Elektrowärmepumpe Luft | C12: bis 1994 | D12: 0.5
C13: ab 1995 | D13: 0.4
A16: Tabelle 22 - Aufwandszahl für bauteilintegrierten Heizflächen (Flächenheizungen); lichte Raumhöhe ≤ 4m | F16: Aufwandszahl für freie Heizflächen - Raumhöhe ≤ 4m
A17: Einflussparameter | D17: eh,ce,0 | F17: Einflussparameter | I17: eh,ce,0
A18: Raumtemperaturregelung | B18: ungeregelt, mit zentraler Zulauftemperaturregelung | D18: 1.149 | F18: Raumtemperaturregelung | G18: ungeregelt, mit zentraler Zulauftemperaturregelung | I18: 1.149
B19: Führungsraumregelung- oder Ein-Rohr-Heizung | D19: 1.107 | G19: Führungsraumregelung- oder Ein-Rohr-Heizung | I19: 1.107
B20: Raumtemperaturregelung (elektromechanisch/elektronisch) | D20: 1.095 | G20: Raumtemperaturregelung (elektromechanisch/elektronisch) | I20: 1.095
B21: P-Regler (vor 1988) | D21: 1.083 | G21: P-Regler (vor 1988) | I21: 1.083
B22: P-Regler, 2-Punkt-Regler (Hysterese ≤ 0,5K | D22: 1.042 | G22: P-Reglera | I22: 1.042
B23: PI-Reglera | D23: 1.042 | G23: PI-Reglera | I23: 1.042
B24: PID-Regler (mit Optimierungsfunktion, z.B. Anwesenheits- management, adaptivem Regler)a | D24: 1.03 | G24: PID-Regler (mit Optimierungsfunktion, z.B. Anwesenheits- management, adaptivem Regler)a | I24: 1.03
A26: Zu- / Abschlag auf Aufwandszahl eh,ce,0 | F26: Zu- / Abschlag auf Aufwandszahl eh,ce,0
D27: ∆eh,ce,1 | I27: ∆eh,ce,1
A28: System | B28: Fußbodenheizung | F28: Übertemperatur | G28: Zwei-Rohr-Heizung und Ein-Rohr-Heizung, erneuert
B29:  Nasssystem | D29: 0.021 | G29: 60K (z.B. 90°C / 70°C) | I29: 0.036
B30:  Trockensystem | D30: 0.012 | G30: 42,5K (z.B. 70°C / 55°C) | I30: 0.021
B31:  System mit niedriger Bedeckung | D31: 0.006 | G31: 30K (z.B. 55°C / 45°C) | I31: 0.015
B32: Wandheizung | D32: 0.045 | G32: 20K (z.B. 45°C / 35°C) | I32: 0.012
B33: Deckenheizung | D33: 0.063 | G33: Ein-Rohr-Heizung (nicht erneuert)
B34: Heizungsanlage in Verbindung mit mechanischer Lüftung | D34: 0 | G34: 60K (z.B. 90°C / 70°C) | I34: 0.048
D35: ∆eh,ce,2 | G35: 42,5K (z.B. 70°C / 55°C) | I35: 0.036
A36: spezifische Wärmeverlust übe angrenzende Flächen | B36: integrierte Heizfläche ohne Mindestdämmung nach DIN EN 1264 (alle Teile) | D36: 0.042 | G36: Heizungsanlage in Verbindung mit mechanischer Lüftung | I36: 0.006
G37: Radiatoren mit Gebläse | I37: 0
B38: integrierte Heizfläche mit Mindestdämmung nach DIN EN 1264 (alle Teile) | D38: 0.015 | I38: ∆eh,ce,2
F39: spezifische Wärmeverlust über Außenbauteile (GF = Glasfläche) | G39: Radiatorenposition Innenwand | I39: 0.039
B40: integrierte Heizfläche einer 100% besseren Dämmung als nach DIN EN 1264 (alle Teile) gefordert | D40: 0.003 | G40: Radiatorenposition Außenwand
G41:  Glasfläche ohne Strahlungsschutz | I41: 0.051
G42:  Glasfläche mit Strahlungsschutz | I42: 0.036
G43:  Außenwand | I43: 0.009
I44: ∆eh,ce,3
...

Sheet Formeln
A3: Jahres-Heizwärmebedarf kWh/a | D3: [Gradtagsfaktor x (Transmissionswärmeverlust + Lüftungswärmeverlust)] - [Nutzungsgrad interner Gewinne x (solare Gewinne + interne Gewinne)]
A5: Interne Wärmegewinne W/m² | D5: 5 x Nutzfläche x Länge der Heizperiode x 0,024 (Länge der Heizperiode im Durchschnitt 185 Tage)
A7: Solare Gewinne | D7: ∑ (Einstrahlung x Energiedurchlassgrad der Fenster x Fläche X Korrekturfaktoren) pro Himmelsrichtung
A9: Wärmebedarf | D9: Transmissionswärmeverlust + Lüftungswärmeverlust
A11: Transmissionswärmeverlust HT | D11: ∑ (Korrekturfaktor x U-Wert x Bauteilfläche) + (Wärmebrückenzuschlag x Hüllfläche des Gebäudes) | S11: Absoluter Wert
A13: spezifischer Transmissionswärmeverlust HT' | D13: Transmissionswärmeverlust HT / thermische Hüllfläche | S13: Flächenbezogen
A15: Nutzfläche ANG | D15: Gebäudevolumen x 0,32
A17: Gradtagszahl Kd/a | D17: Außentemperatur unter einer festgelegten Heizgrenztemperatur (regional) (Bsp.: dena-Energiepass)
A19: Gradtagsfaktor kKh | D19: Gradtagszahl x Faktor 0,024
A21: Lüftungswärmetransferkoeffizient HV [W/K] | D21: 0,34 x Luftwechselrate x beheiztes Luftvolumen (Luftwechselrate aus DIN 18599 Tabelle 12 - 14)
A26: Kleinbuchstaben beziehen sich auf m² / Großbuchstaben beziehen sich auf den Jahreswert
